Workbook

Sheet CATATAN
A2: Pinjaman
A3: NO | B3: NAMA | C3: BULAN | D3: JUMLAH
A4: 1 | B4: Upy | C4: Januari | D4: 50000000 | E4: lunas
A5: 2 | B5: Upy | D5: 17000000 | E5: Lunas
A6: 3 | B6: Upy | D6: 5000000 | E6: Lunas
A7: 4 | B7: Upy | D7: 29000000
A8: 5 | B8: Upy | D8: 5000000
A9: 6 | B9: Upy | C9: Februari | D9: 5000000
A10: 7 | B10: Upy | D10: 5000000
A11: 8 | B11: Upy | D11: 3000000
A12: 9 | B12: Upy | D12: 70000000
A13: 10 | B13: Upy
A14: 11 | B14: Upy | G14: =D20-Januari!J73 -> 0 | I14: Hutang Ia ke kaupy
A15: 12 | B15: Upy
A16: 13 | B16: Upy
A17: 14 | B17: Upy
A18: 15 | B18: Upy
A19: 16 | B19: Upy
A20: TOTAL | D20: =SUM(D4:D19) -> 189000000
B21: Sisa Uang Pinjaman Yang Terpakai
A23: 1000000 | D23: Masih ada di ka upy uang kabid SMA, ia tutup pakai uangnya jul

Sheet HUTANG LAIN2
A1: RINCIAN PERJALANAN DINAS HALUT
A2: NO | B2: NAMA | C2: GOL/ESELON | D2: TUJUAN | E2: UANG HARIAN | H2: PENGINAPAN | K2: TRANSPORTASI | L2: TOTAL YANG DITERIMA
E3: BIAYA | F3: HARI | G3: JUMLAH | H3: BIAYA | I3: HARI | J3: JUMLAH
A4: 1 | B4: Kabid SMA | C4: III | D4: TOBELO | E4: 430000 | F4: 4 | G4: 1720000 | H4: 450000 | I4: 3 | J4: 1350000 | K4: 900000 | L4: 3970000
A5: RINCIAN PERJALANAN DINAS HALBAR
A6: NO | B6: NAMA | C6: GOL/ESELON | D6: TUJUAN | E6: UANG HARIAN | H6: PENGINAPAN | K6: TRANSPORTASI | L6: TOTAL YANG DITERIMA
E7: BIAYA | F7: HARI | G7: JUMLAH | H7: BIAYA | I7: HARI | J7: JUMLAH
A8: 1 | B8: Kabid SMA | C8: III | D8: HALBAR | E8: 430000 | F8: 4 | G8: 1720000 | H8: 450000 | I8: 3 | J8: 1350000 | K8: 850000 | L8: 3920000
A9: T O T A L | L9: =SUM(L4+L8) -> 7890000
A11: KETERANGAN PEMOTONGAN : | C11: Tobelo Panjar 1 | D11: 46037 | E11: 1500000
C12: Tobelo Panjar 1 | D12: 46038 | E12: 1000000
C13: Halbar Panjar 1 | D13: 46062 | E13: 2200000
C14: BBM Ke Tawa | D14: 46059 | E14: 500000
C15: Uang Spead | D15: 46055 | E15: 250000
C16: TOTAL | D16: =E11+E12+E13+E14+E15 -> 5450000
C17: TOTAL SELURUHNYA | D17: =L9-D16 -> 2440000

Sheet LISTRIK
A1: DAFTAR TAGIHAN LISTRIK PADA
A2: DINAS PENDIDKAN DAN KEBUDAYAAN PROVINSI MALUKU UTARA
A4: BULAN: JANUARI
A5: NO | B5: NAMA REKENING | C5: NO REKENING PLN | D5: NILAI
A6: 1 | B6: KANTOR DIKNAS | C6: 415300019711
A7: 2 | B7: VIDIOTRON | C7: 415300132197
A8: T O T A L | D8: =SUM(D6:D7) -> 0
A10: BULAN: FEBRUARI
A11: NO | B11: NAMA REKENING | C11: NO REKENING PLN | D11: NILAI
A12: 1 | B12: KANTOR DIKNAS | C12: 415300019711 | D12: 18220464 | E12: Lunas
A13: 2 | B13: VIDIOTRON | C13: 415300132197 | D13: 1563568 | E13: Lunas
A14: T O T A L | D14: =SUM(D12:D13) -> 19784032
A16: BULAN: MARET
A17: NO | B17: NAMA REKENING | C17: NO REKENING PLN | D17: NILAI
A18: 1 | B18: KANTOR DIKNAS | C18: 415300019711 | D18: 18220464
A19: 2 | B19: VIDIOTRON | C19: 415300132197 | D19: 1563568
A20: T O T A L | D20: =SUM(D18:D19) -> 19784032

Sheet INTERNET
A1: DAFTAR TAGIHAN INTERNET (INDIHOME) PADA
A2: DINAS PENDIDKAN DAN KEBUDAYAAN PROVINSI MALUKU UTARA
A4: BULAN: JANUARI
A5: NO | B5: NAMA RUANGAN | C5: NO INTERNET | D5: NILAI | E5: BIAYA ADMIN | F5: TOTAL PEMBAYARAN | G5: KET
A6: 1 | B6: RUANGAN KADIS | C6: NOMOR PELANGGAN 172328202150 | F6: =SUM(D6+E6) -> 0 | G6: Lunas
A7: 2 | B7: BIDANG KEUANGAN | C7: NOMOR PELANGGAN 172328204742 | F7: =SUM(D7+E7) -> 0 | G7: Lunas
A8: 3 | B8: BIDANG KEPEGAWAIAN | C8: NOMOR PELANGGAN 172328204653 | F8: =SUM(D8+E8) -> 0 | G8: Lunas
A9: 4 | B9: BIDANG PERENCANAAN | C9: NOMOR PELANGGAN 172328204576 | F9: =SUM(D9+E9) -> 0 | G9: Lunas
A10: 5 | B10: BIDANG GTK | C10: NOMOR PELANGGAN 172328204665 | F10: =SUM(D10+E10) -> 0 | G10: Lunas
A11: 6 | B11: BIDANG KEBUDAYAAN | C11: NOMOR PELANGGAN 172328204658 | F11: =SUM(D11+E11) -> 0 | G11: Lunas
A12: 7 | B12: BIDANG PMPK | C12: NOMOR PELANGGAN 172328204876 | F12: =SUM(D12+E12) -> 0 | G12: Lunas
A13: 8 | B13: BIDANG SMA | C13: NOMOR PELANGGAN 172328204741 | F13: =SUM(D13+E13) -> 0 | G13: Lunas
A14: 9 | B14: BIDANG SMK | C14: NOMOR PELANGGAN 172328204509 | F14: =SUM(D14+E14) -> 0 | G14: Lunas
A15: T O T A L | F15: =SUM(F6:F14) -> 0
A17: BULAN: FEBRUARI
A18: NO | B18: NAMA RUANGAN | C18: NO INTERNET | D18: NILAI | E18: BIAYA ADMIN | F18: TOTAL PEMBAYARAN | G18: KET
A19: 1 | B19: RUANGAN KADIS | C19: NOMOR PELANGGAN 172328202150 | D19: 496170 | E19: 3500 | F19: =SUM(D19+E19) -> 499670 | G19: Lunas
A20: 2 | B20: BIDANG KEUANGAN | C20: NOMOR PELANGGAN 172328204742 | D20: 496170 | E20: 3500 | F20: =SUM(D20+E20) -> 499670 | G20: Lunas
A21: 3 | B21: BIDANG KEPEGAWAIAN | C21: NOMOR PELANGGAN 172328204653 | D21: 521700 | E21: 3500 | F21: =SUM(D21+E21) -> 525200 | G21: Lunas
A22: 4 | B22: BIDANG PERENCANAAN | C22: NOMOR PELANGGAN 172328204576 | D22: 618270 | E22: 3500 | F22: =SUM(D22+E22) -> 621770 | G22: Lunas
A23: 5 | B23: BIDANG GTK | C23: NOMOR PELANGGAN 172328204665 | D23: 521700 | E23: 3500 | F23: =SUM(D23+E23) -> 525200 | G23: Lunas
A24: 6 | B24: BIDANG KEBUDAYAAN | C24: NOMOR PELANGGAN 172328204658 | D24: 521700 | E24: 3500 | F24: =SUM(D24+E24) -> 525200 | G24: Lunas
A25: 7 | B25: BIDANG PMPK | C25: NOMOR PELANGGAN 172328204876 | D25: 496170 | E25: 3500 | F25: =SUM(D25+E25) -> 499670 | G25: Lunas
A26: 8 | B26: BIDANG SMA | C26: NOMOR PELANGGAN 172328204741 | D26: 521700 | E26: 3500 | F26: =SUM(D26+E26) -> 525200 | G26: Lunas
A27: 9 | B27: BIDANG SMK | C27: NOMOR PELANGGAN 172328204509 | D27: 496170 | E27: 3500 | F27: =SUM(D27+E27) -> 499670 | G27: Lunas
A28: T O T A L | F28: =SUM(F19:F27) -> 4721250
A30: BULAN: MARET
A31: NO | B31: NAMA RUANGAN | C31: NO INTERNET | D31: NILAI | E31: BIAYA ADMIN | F31: TOTAL PEMBAYARAN | G31: KET
A32: 1 | B32: RUANGAN KADIS | C32: NOMOR PELANGGAN 172328202150 | D32: 496170 | E32: 3500 | F32: =SUM(D32+E32) -> 499670
A33: 2 | B33: BIDANG KEUANGAN | C33: NOMOR PELANGGAN 172328204742 | D33: 496170 | E33: 3500 | F33: =SUM(D33+E33) -> 499670
A34: 3 | B34: BIDANG KEPEGAWAIAN | C34: NOMOR PELANGGAN 172328204653 | D34: 521700 | E34: 3500 | F34: =SUM(D34+E34) -> 525200
A35: 4 | B35: BIDANG PERENCANAAN | C35: NOMOR PELANGGAN 172328204576 | D35: 618270 | E35: 3500 | F35: =SUM(D35+E35) -> 621770
A36: 5 | B36: BIDANG GTK | C36: NOMOR PELANGGAN 172328204665 | D36: 521700 | E36: 3500 | F36: =SUM(D36+E36) -> 525200
A37: 6 | B37: BIDANG KEBUDAYAAN | C37: NOMOR PELANGGAN 172328204658 | D37: 521700 | E37: 3500 | F37: =SUM(D37+E37) -> 525200
A38: 7 | B38: BIDANG PMPK | C38: NOMOR PELANGGAN 172328204876 | D38: 496170 | E38: 3500 | F38: =SUM(D38+E38) -> 499670
A39: 8 | B39: BIDANG SMA | C39: NOMOR PELANGGAN 172328204741 | D39: 521700 | E39: 3500 | F39: =SUM(D39+E39) -> 525200
A40: 9 | B40: BIDANG SMK | C40: NOMOR PELANGGAN 172328204509 | D40: 496170 | E40: 3500 | F40: =SUM(D40+E40) -> 499670
A41: T O T A L | F41: =SUM(F32:F40) -> 4721250

Sheet Januari
A1: LEMBAR KONTROL HUTANG
A2: Periode 01 Januari s/d 31 Januari 2026
A4: No | B4: Hari, Tanggal | C4: Jumlah Nominal yang dikeluarkan | D4: Jumlah yang diterima | E4: Pihak Ke 3 | F4: Petugas Penerima | G4: Pejabat yang ditunjuk sbg Penerima | H4: Waktu Penyerahan | I4: Lokasi Penyerahan | J4: Tujuan/Keperluan | L4: SUMBER DANA | M4: STATUS | N4: NOMINAL BAYAR SEBAGIAN | O4: BUKTI
A6: 1 | B6: 46032 | C6: 3569000 | D6: 3569000 | E6: Yulia Travel | F6: Yulia | G6: Vivi | I6: Ternate | J6: Perjalanan Dinas | K6: Abubakar Hi. Abdullah, S.pd., Msi | L6: DANSAV UPY | M6: LUNAS
A7: 2 | B7: 46032 | C7: 3569000 | D7: 3569000 | E7: Yulia Travel | F7: Yulia | G7: Vivi | I7: Ternate | J7: Perjalanan Dinas | K7: Sofyan S.Kom., M.M | L7: DANSAV UPY | M7: LUNAS
A8: 3 | C8: 1464300 | D8: 1464300 | J8: Reschedule tanggal 21 Januari 2026 | L8: DANSAV UPY | M8: LUNAS
A9: 4 | C9: 1274000 | D9: 1274000 | J9: Reschedule tanggal 27 Januari 2026 | L9: DANSAV UPY | M9: LUNAS
A10: 5 | C10: 700000 | D10: 700000 | J10: Reschedule 25 Januari 2026 | L10: DANSAV UPY | M10: LUNAS
A11: 6 | B11: 46036 | C11: 2200000 | D11: - | E11: Mutiara | F11: Pa Armin | G11: Vivi | H11: Pagi | I11: Sofifi, Pelabuhan Spead Sofifi | J11: Persiapan Kegiatan Peningkatan Kompetensi literasi digital dan Pemahaman Artificial Inteligence (AI) | L11: VIVI | M11: HUTANG
A12: 7 | C12: 150000 | D12: 150000 | E12: Tukang CAP | F12: Yulia | G12: Vivi | H12: Sore | I12: Sofifi, Kantor DIKBUD | J12: Pembuatan CAP Dinas Baru Untuk bendahara | L12: DANSAV UPY | M12: LUNAS
A13: 8 | B13: Kamis 15 januari 2026 | C13: 500000 | D13: 500000 | E13: Ayu | F13: Ayu | G13: Vivi | H13: Pagi | I13: Sofifi, Kantor DIKBUD | J13: Makan nimum kadis | L13: VIVI | M13: HUTANG
A14: 9 | B14: Kamis 15 januari 2026 | C14: 3100000 | D14: - | E14: Teluk Persia 1 dan 2 | F14: - | G14: Vivi | H14: Pagi | I14: Sofifi, Pelabuhan Spead Sofifi | J14: RoadShow | L14: VIVI | M14: HUTANG
A15: 10 | B15: 46038 | F15: T A N G G A L M E R A H
A16: 11 | B16: 46041 | C16: 18750000 | D16: 18750000 | E16: Teras Atiqa | F16: Yulia | G16: Vivi | H16: Pagi | I16: Aula SMK Negeri 2 Kota Ternate | J16: Kegiatan Peningkatan Kompetensi literasi digital dan Pemahaman Artificial Inteligence (AI) | L16: DANSAV UPY | M16: LUNAS
A17: 12 | B17: 46041 | C17: 20928000 | D17: 20928000 | E17: PDAM, dan PLN | F17: PDAM dan PLN | G17: Vivi | H17: Pagi | I17: Ternate | J17: Pembayaran Listrik dan PDAM | L17: VIVI | M17: HUTANG
A18: 13 | B18: 46041 | C18: 1000000 | D18: 1000000 | E18: Ayu | F18: Ayu | G18: Vivi | H18: Pagi | I18: Sofifi, Kantor DIKBUD | J18: Makan nimum kadis | L18: VIVI | M18: HUTANG
A19: 14 | B19: 46042 | C19: 18750000 | D19: 18750000 | E19: Teras Atiqa | F19: Yulia | G19: Vivi | H19: Pagi | I19: Aula SMK Negeri 2 Kota Ternate | J19: Kegiatan Peningkatan Kompetensi literasi digital dan Pemahaman Artificial Inteligence (AI) | L19: DANSAV UPY | M19: LUNAS
A20: 15 | B20: 46043 | C20: 1200000 | D20: 1200000 | E20: Teluk Persia 2 (Canox) | F20: Yulia | G20: Vivi | H20: Pagi | I20: Sofifi, Pelabuhan Spead Sofifi | J20: Ke Kantor | L20: DANSAV UPY | M20: LUNAS
A21: 16 | B21: 46043 | C21: 700000 | D21: 700000 | E21: Teluk Persia 2 (Canox) | F21: Yulia | G21: Vivi | H21: Pagi | I21: Sofifi, Pelabuhan Spead Sofifi | J21: pulang batal | L21: DANSAV UPY | M21: LUNAS
A22: 17 | C22: 550000 | D22: - | E22: Kapal Cepat Cantika | F22: Yulia | G22: Vivi | H22: Sore | I22: Sofifi, Pelabuhan Kacep Sofifi | L22: VIVI | M22: HUTANG
A23: 18 | B23: 46043 | C23: 3563400 | D23: 3563400 | E23: Yulia Travel | F23: Yulia | G23: Vivi | H23: Malam | I23: Ternate | J23: Perjadin Pergi | K23: Abubakar Hi. Abdullah, S.pd., Msi | L23: DANSAV UPY | M23: LUNAS
A24: 19 | C24: 2072095 | D24: 700000 | J24: Reschedule 26 januari 2026 | L24: DANSAV UPY | M24: LUNAS
A25: 20 | B25: 46044 | C25: 50000 | D25: 50000 | E25: Yulia | F25: Yulia | G25: Vivi | H25: Sore | I25: Ternate | J25: Cap bbm | L25: DANSAV UPY | M25: LUNAS
A26: 21 | B26: 46049 | C26: 270000 | D26: 270000 | E26: Om Engko | F26: Yulia | G26: Vivi | H26: Pagi | I26: Sofifi, Kantor DIKBUD | J26: pembuatan Bendera merah putih 3 Lembar | L26: VIVI | M26: HUTANG
A27: 22 | B27: 46048 | C27: 3800000 | D27: 3800000 | E27: ...Elektronik | F27: Yulia | G27: Vivi | H27: Siang | I27: Sofifi | J27: Pembelian ShowCase | L27: DANSAV UPY | M27: LUNAS
A28: 23 | B28: 46048 | C28: 1851000 | D28: 1851000 | E28: Toko Grosir | F28: - | G28: Vivi | H28: Siang | I28: Sofifi | J28: Minuman Kadis | L28: VIVI | M28: HUTANG
A29: 24 | B29: 46048 | C29: 3681720 | D29: 3681720 | E29: Yulia Travel | F29: Yulia | G29: Vivi | H29: Pagi | I29: Ternate | J29: Perjalanan Dinas | K29: Irwan Sergi | L29: DANSAV UPY | M29: LUNAS
A30: 26 | B30: 18 | C30: 200000 | D30: 200000 | E30: CV intisari | F30: Om Dade | G30: Vivi | H30: Sore | I30: Sofifi, Kantor DIKBUD | J30: Pembeliat cat | L30: VIVI | M30: HUTANG
A31: 27 | B31: 46050 | C31: 3704238 | D31: 3704238 | E31: Tiket.com | F31: Sofyan | G31: Vivi | H31: Malam | I31: Ternate | J31: Perjalanan Dinas, Pak Kadis pulang mendadak | K31: Abubakar Hi. Abdullah, S.pd., Msi | L31: DANSAV UPY | M31: LUNAS
A32: 28 | B32: 46050 | C32: 315000 | D32: 315000 | E32: Aneka Baut | F32: Yulia | G32: Vivi | H32: Sore | I32: Sofifi, Kantor DIKBUD | J32: Pembelian Lampu | L32: VIVI | M32: HUTANG
A33: 29 | B33: 46051 | C33: 209700 | D33: 209700 | E33: Mimy dan Jana | F33: Yulia | G33: Vivi | H33: Pagi | I33: Sofifi, Kantor DIKBUD | J33: Beli Ember 1 dan Gayung 2 Untuk Kamar Mandi Wanita Lantai 1 | L33: DANSAV UPY | M33: LUNAS
A34: 30 | B34: 46051 | C34: 762500 | D34: 762500 | E34: Livin mandiri Ireine May Lady Prang | F34: Yulia | G34: Vivi | H34: Pagi | I34: Sofifi, Kantor DIKBUD | J34: Beli kalung Bunga buat kegiatan BMPS | L34: DANSAV UPY | M34: LUNAS
A35: 31 | B35: 46051 | C35: 1000000 | D35: 1000000 | E35: Ayu | F35: Yulia | G35: Vivi | H35: Pagi | I35: Sofifi, Kantor DIKBUD | J35: Makanan Kadis dan kue | L35: DANSAV UPY | M35: LUNAS
A36: 32 | B36: 46051 | C36: 40600000 | D36: 40600000 | E36: Teras Atiqah | F36: Yulia | G36: Vivi | H36: Pagi | I36: Sofifi, Kantor DIKBUD | J36: MaMi Kegiatan Pelantikan BMPS Malut Periode 2026-2036dan serasehan pendidikan | L36: DANSAV UPY | M36: LUNAS
D37: 6600000 | J37: MaMi Kegiatan Pelantikan BMPS Malut Periode 2026-2036dan serasehan pendidikan | L37: DANSAV UPY | M37: BAYAR SEBAGIAN | N37: 6600000
A38: 33 | B38: 46051 | C38: 1200000 | D38: 1200000 | E38: Teluk Persia 2 (Canox) | F38: Yulia | G38: Vivi | H38: Pagi | I38: Sofifi, Pelabuhan Spead Sofifi | J38: Ke ternate | L38: DANSAV UPY | M38: LUNAS
A39: 34 | B39: 46051 | C39: 3681720 | D39: 3681720 | E39: Yulia Travel | F39: Yulia | G39: Vivi | H39: Malam | I39: Ternate | J39: Perjadin Pulang | K39: Irwan Sergi | L39: DANSAV UPY | M39: LUNAS
A40: 35 | B40: 46051 | C40: 750000 | D40: 750000 | E40: Tenda Rauda | F40: Pak Upy | G40: Vivi | H40: Siang | I40: Sofifi, Kantor DIKBUD | J40: Kegiatan Pelantikan BMPS Malut Periode 2026-2036 dan serasehan pendidikan | L40: DANSAV UPY | M40: LUNAS
A41: 36 | B41: 46051 | C41: 250000 | D41: 250000 | E41: Semeru | F41: Yulia | G41: Vivi | H41: Pagi | I41: Ternate | J41: CAP bbm | L41: DANSAV UPY | M41: LUNAS
A42: 37 | B42: 46052 | C42: 122500 | D42: 122500 | E42: Toko Amanah | F42: Yulia | G42: Vivi | H42: Malam | I42: Ternate | J42: Pembelian kertas | L42: DANSAV UPY | M42: LUNAS
...

Sheet Rincian_Saving_Jan
B1: SUMBER DANA : | C1: DANSAV UPY | D1: <- PILIH DARI SINI | E1: Catatan : Data dalam tabel otomatis, jangan di rubah atau klik
A3: Hari, Tanggal | B3: Jumlah Nominal yang dikeluarkan | C3: Jumlah yang diterima | D3: Pihak Ke 3 | E3: Petugas Penerima | F3: Pejabat yang ditunjuk sbg Penerima | G3: Waktu Penyerahan | H3: Lokasi Penyerahan | I3: Tujuan/Keperluan
A4: {=IFERROR(INDEX(Januari!B$6:B$44,SMALL(IF(Januari!$L$6:$L$44=$C$1,ROW(Januari!$L$6:$L$44)-ROW(Januari!$L$6)+1),ROW(A1))),"")} -> 46032 | B4: {=IF($A4="","",INDEX(Januari!C$6:C$44,SMALL(IF(Januari!$L$6:$L$44=$C$1,ROW(Januari!$L$6:$L$44)-ROW(Januari!$L$6)+1),ROW(A1))))} -> 3569000 | C4: {=IF($A4="","",INDEX(Januari!D$6:D$44,SMALL(IF(Januari!$L$6:$L$44=$C$1,ROW(Januari!$L$6:$L$44)-ROW(Januari!$L$6)+1),ROW(B1))))} -> 3569000 | D4: {=IF($A4="","",INDEX(Januari!E$6:E$44,SMALL(IF(Januari!$L$6:$L$44=$C$1,ROW(Januari!$L$6:$L$44)-ROW(Januari!$L$6)+1),ROW(C1))))} -> Yulia Travel | E4: {=IF($A4="","",INDEX(Januari!F$6:F$44,SMALL(IF(Januari!$L$6:$L$44=$C$1,ROW(Januari!$L$6:$L$44)-ROW(Januari!$L$6)+1),ROW(D1))))} -> Yulia | F4: {=IF($A4="","",INDEX(Januari!G$6:G$44,SMALL(IF(Januari!$L$6:$L$44=$C$1,ROW(Januari!$L$6:$L$44)-ROW(Januari!$L$6)+1),ROW(E1))))} -> Vivi | G4: {=IF($A4="","",INDEX(Januari!H$6:H$44,SMALL(IF(Januari!$L$6:$L$44=$C$1,ROW(Januari!$L$6:$L$44)-ROW(Januari!$L$6)+1),ROW(F1))))} -> 0 | H4: {=IF($A4="","",INDEX(Januari!I$6:I$44,SMALL(IF(Januari!$L$6:$L$44=$C$1,ROW(Januari!$L$6:$L$44)-ROW(Januari!$L$6)+1),ROW(G1))))} -> Ternate | I4: {=IF($A4="","",INDEX(Januari!J$6:J$44,SMALL(IF(Januari!$L$6:$L$44=$C$1,ROW(Januari!$L$6:$L$44)-ROW(Januari!$L$6)+1),ROW(H1))))} -> Perjalanan Dinas | J4: {=IF($A4="","",INDEX(Januari!K$6:K$44,SMALL(IF(Januari!$L$6:$L$44=$C$1,ROW(Januari!$L$6:$L$44)-ROW(Januari!$L$6)+1),ROW(I1))))} -> Abubakar Hi. Abdullah, S.pd., Msi
A5: {=IFERROR(INDEX(Januari!B$6:B$44,SMALL(IF(Januari!$L$6:$L$44=$C$1,ROW(Januari!$L$6:$L$44)-ROW(Januari!$L$6)+1),ROW(A2))),"")} -> 46032 | B5: {=IF($A5="","",INDEX(Januari!C$6:C$44,SMALL(IF(Januari!$L$6:$L$44=$C$1,ROW(Januari!$L$6:$L$44)-ROW(Januari!$L$6)+1),ROW(A2))))} -> 3569000 | C5: {=IF($A5="","",INDEX(Januari!D$6:D$44,SMALL(IF(Januari!$L$6:$L$44=$C$1,ROW(Januari!$L$6:$L$44)-ROW(Januari!$L$6)+1),ROW(B2))))} -> 3569000 | D5: {=IF($A5="","",INDEX(Januari!E$6:E$44,SMALL(IF(Januari!$L$6:$L$44=$C$1,ROW(Januari!$L$6:$L$44)-ROW(Januari!$L$6)+1),ROW(C2))))} -> Yulia Travel | E5: {=IF($A5="","",INDEX(Januari!F$6:F$44,SMALL(IF(Januari!$L$6:$L$44=$C$1,ROW(Januari!$L$6:$L$44)-ROW(Januari!$L$6)+1),ROW(D2))))} -> Yulia | F5: {=IF($A5="","",INDEX(Januari!G$6:G$44,SMALL(IF(Januari!$L$6:$L$44=$C$1,ROW(Januari!$L$6:$L$44)-ROW(Januari!$L$6)+1),ROW(E2))))} -> Vivi | G5: {=IF($A5="","",INDEX(Januari!H$6:H$44,SMALL(IF(Januari!$L$6:$L$44=$C$1,ROW(Januari!$L$6:$L$44)-ROW(Januari!$L$6)+1),ROW(F2))))} -> 0 | H5: {=IF($A5="","",INDEX(Januari!I$6:I$44,SMALL(IF(Januari!$L$6:$L$44=$C$1,ROW(Januari!$L$6:$L$44)-ROW(Januari!$L$6)+1),ROW(G2))))} -> Ternate | I5: {=IF($A5="","",INDEX(Januari!J$6:J$44,SMALL(IF(Januari!$L$6:$L$44=$C$1,ROW(Januari!$L$6:$L$44)-ROW(Januari!$L$6)+1),ROW(H2))))} -> Perjalanan Dinas | J5: {=IF($A5="","",INDEX(Januari!K$6:K$44,SMALL(IF(Januari!$L$6:$L$44=$C$1,ROW(Januari!$L$6:$L$44)-ROW(Januari!$L$6)+1),ROW(I2))))} -> Sofyan S.Kom., M.M
A6: {=IFERROR(INDEX(Januari!B$6:B$44,SMALL(IF(Januari!$L$6:$L$44=$C$1,ROW(Januari!$L$6:$L$44)-ROW(Januari!$L$6)+1),ROW(A3))),"")} -> 0 | B6: {=IF($A6="","",INDEX(Januari!C$6:C$44,SMALL(IF(Januari!$L$6:$L$44=$C$1,ROW(Januari!$L$6:$L$44)-ROW(Januari!$L$6)+1),ROW(A3))))} -> 1464300 | C6: {=IF($A6="","",INDEX(Januari!D$6:D$44,SMALL(IF(Januari!$L$6:$L$44=$C$1,ROW(Januari!$L$6:$L$44)-ROW(Januari!$L$6)+1),ROW(B3))))} -> 1464300 | D6: {=IF($A6="","",INDEX(Januari!E$6:E$44,SMALL(IF(Januari!$L$6:$L$44=$C$1,ROW(Januari!$L$6:$L$44)-ROW(Januari!$L$6)+1),ROW(C3))))} -> 0 | E6: {=IF($A6="","",INDEX(Januari!F$6:F$44,SMALL(IF(Januari!$L$6:$L$44=$C$1,ROW(Januari!$L$6:$L$44)-ROW(Januari!$L$6)+1),ROW(D3))))} -> 0 | F6: {=IF($A6="","",INDEX(Januari!G$6:G$44,SMALL(IF(Januari!$L$6:$L$44=$C$1,ROW(Januari!$L$6:$L$44)-ROW(Januari!$L$6)+1),ROW(E3))))} -> 0 | G6: {=IF($A6="","",INDEX(Januari!H$6:H$44,SMALL(IF(Januari!$L$6:$L$44=$C$1,ROW(Januari!$L$6:$L$44)-ROW(Januari!$L$6)+1),ROW(F3))))} -> 0 | H6: {=IF($A6="","",INDEX(Januari!I$6:I$44,SMALL(IF(Januari!$L$6:$L$44=$C$1,ROW(Januari!$L$6:$L$44)-ROW(Januari!$L$6)+1),ROW(G3))))} -> 0 | I6: {=IF($A6="","",INDEX(Januari!J$6:J$44,SMALL(IF(Januari!$L$6:$L$44=$C$1,ROW(Januari!$L$6:$L$44)-ROW(Januari!$L$6)+1),ROW(H3))))} -> Reschedule tanggal 21 Januari 2026 | J6: {=IF($A6="","",INDEX(Januari!K$6:K$44,SMALL(IF(Januari!$L$6:$L$44=$C$1,ROW(Januari!$L$6:$L$44)-ROW(Januari!$L$6)+1),ROW(I3))))} -> 0
A7: {=IFERROR(INDEX(Januari!B$6:B$44,SMALL(IF(Januari!$L$6:$L$44=$C$1,ROW(Januari!$L$6:$L$44)-ROW(Januari!$L$6)+1),ROW(A4))),"")} -> 0 | B7: {=IF($A7="","",INDEX(Januari!C$6:C$44,SMALL(IF(Januari!$L$6:$L$44=$C$1,ROW(Januari!$L$6:$L$44)-ROW(Januari!$L$6)+1),ROW(A4))))} -> 1274000 | C7: {=IF($A7="","",INDEX(Januari!D$6:D$44,SMALL(IF(Januari!$L$6:$L$44=$C$1,ROW(Januari!$L$6:$L$44)-ROW(Januari!$L$6)+1),ROW(B4))))} -> 1274000 | D7: {=IF($A7="","",INDEX(Januari!E$6:E$44,SMALL(IF(Januari!$L$6:$L$44=$C$1,ROW(Januari!$L$6:$L$44)-ROW(Januari!$L$6)+1),ROW(C4))))} -> 0 | E7: {=IF($A7="","",INDEX(Januari!F$6:F$44,SMALL(IF(Januari!$L$6:$L$44=$C$1,ROW(Januari!$L$6:$L$44)-ROW(Januari!$L$6)+1),ROW(D4))))} -> 0 | F7: {=IF($A7="","",INDEX(Januari!G$6:G$44,SMALL(IF(Januari!$L$6:$L$44=$C$1,ROW(Januari!$L$6:$L$44)-ROW(Januari!$L$6)+1),ROW(E4))))} -> 0 | G7: {=IF($A7="","",INDEX(Januari!H$6:H$44,SMALL(IF(Januari!$L$6:$L$44=$C$1,ROW(Januari!$L$6:$L$44)-ROW(Januari!$L$6)+1),ROW(F4))))} -> 0 | H7: {=IF($A7="","",INDEX(Januari!I$6:I$44,SMALL(IF(Januari!$L$6:$L$44=$C$1,ROW(Januari!$L$6:$L$44)-ROW(Januari!$L$6)+1),ROW(G4))))} -> 0 | I7: {=IF($A7="","",INDEX(Januari!J$6:J$44,SMALL(IF(Januari!$L$6:$L$44=$C$1,ROW(Januari!$L$6:$L$44)-ROW(Januari!$L$6)+1),ROW(H4))))} -> Reschedule tanggal 27 Januari 2026 | J7: {=IF($A7="","",INDEX(Januari!K$6:K$44,SMALL(IF(Januari!$L$6:$L$44=$C$1,ROW(Januari!$L$6:$L$44)-ROW(Januari!$L$6)+1),ROW(I4))))} -> 0
A8: {=IFERROR(INDEX(Januari!B$6:B$44,SMALL(IF(Januari!$L$6:$L$44=$C$1,ROW(Januari!$L$6:$L$44)-ROW(Januari!$L$6)+1),ROW(A5))),"")} -> 0 | B8: {=IF($A8="","",INDEX(Januari!C$6:C$44,SMALL(IF(Januari!$L$6:$L$44=$C$1,ROW(Januari!$L$6:$L$44)-ROW(Januari!$L$6)+1),ROW(A5))))} -> 700000 | C8: {=IF($A8="","",INDEX(Januari!D$6:D$44,SMALL(IF(Januari!$L$6:$L$44=$C$1,ROW(Januari!$L$6:$L$44)-ROW(Januari!$L$6)+1),ROW(B5))))} -> 700000 | D8: {=IF($A8="","",INDEX(Januari!E$6:E$44,SMALL(IF(Januari!$L$6:$L$44=$C$1,ROW(Januari!$L$6:$L$44)-ROW(Januari!$L$6)+1),ROW(C5))))} -> 0 | E8: {=IF($A8="","",INDEX(Januari!F$6:F$44,SMALL(IF(Januari!$L$6:$L$44=$C$1,ROW(Januari!$L$6:$L$44)-ROW(Januari!$L$6)+1),ROW(D5))))} -> 0 | F8: {=IF($A8="","",INDEX(Januari!G$6:G$44,SMALL(IF(Januari!$L$6:$L$44=$C$1,ROW(Januari!$L$6:$L$44)-ROW(Januari!$L$6)+1),ROW(E5))))} -> 0 | G8: {=IF($A8="","",INDEX(Januari!H$6:H$44,SMALL(IF(Januari!$L$6:$L$44=$C$1,ROW(Januari!$L$6:$L$44)-ROW(Januari!$L$6)+1),ROW(F5))))} -> 0 | H8: {=IF($A8="","",INDEX(Januari!I$6:I$44,SMALL(IF(Januari!$L$6:$L$44=$C$1,ROW(Januari!$L$6:$L$44)-ROW(Januari!$L$6)+1),ROW(G5))))} -> 0 | I8: {=IF($A8="","",INDEX(Januari!J$6:J$44,SMALL(IF(Januari!$L$6:$L$44=$C$1,ROW(Januari!$L$6:$L$44)-ROW(Januari!$L$6)+1),ROW(H5))))} -> Reschedule 25 Januari 2026 | J8: {=IF($A8="","",INDEX(Januari!K$6:K$44,SMALL(IF(Januari!$L$6:$L$44=$C$1,ROW(Januari!$L$6:$L$44)-ROW(Januari!$L$6)+1),ROW(I5))))} -> 0
A9: {=IFERROR(INDEX(Januari!B$6:B$44,SMALL(IF(Januari!$L$6:$L$44=$C$1,ROW(Januari!$L$6:$L$44)-ROW(Januari!$L$6)+1),ROW(A6))),"")} -> 0 | B9: {=IF($A9="","",INDEX(Januari!C$6:C$44,SMALL(IF(Januari!$L$6:$L$44=$C$1,ROW(Januari!$L$6:$L$44)-ROW(Januari!$L$6)+1),ROW(A6))))} -> 150000 | C9: {=IF($A9="","",INDEX(Januari!D$6:D$44,SMALL(IF(Januari!$L$6:$L$44=$C$1,ROW(Januari!$L$6:$L$44)-ROW(Januari!$L$6)+1),ROW(B6))))} -> 150000 | D9: {=IF($A9="","",INDEX(Januari!E$6:E$44,SMALL(IF(Januari!$L$6:$L$44=$C$1,ROW(Januari!$L$6:$L$44)-ROW(Januari!$L$6)+1),ROW(C6))))} -> Tukang CAP | E9: {=IF($A9="","",INDEX(Januari!F$6:F$44,SMALL(IF(Januari!$L$6:$L$44=$C$1,ROW(Januari!$L$6:$L$44)-ROW(Januari!$L$6)+1),ROW(D6))))} -> Yulia | F9: {=IF($A9="","",INDEX(Januari!G$6:G$44,SMALL(IF(Januari!$L$6:$L$44=$C$1,ROW(Januari!$L$6:$L$44)-ROW(Januari!$L$6)+1),ROW(E6))))} -> Vivi | G9: {=IF($A9="","",INDEX(Januari!H$6:H$44,SMALL(IF(Januari!$L$6:$L$44=$C$1,ROW(Januari!$L$6:$L$44)-ROW(Januari!$L$6)+1),ROW(F6))))} -> Sore | H9: {=IF($A9="","",INDEX(Januari!I$6:I$44,SMALL(IF(Januari!$L$6:$L$44=$C$1,ROW(Januari!$L$6:$L$44)-ROW(Januari!$L$6)+1),ROW(G6))))} -> Sofifi, Kantor DIKBUD | I9: {=IF($A9="","",INDEX(Januari!J$6:J$44,SMALL(IF(Januari!$L$6:$L$44=$C$1,ROW(Januari!$L$6:$L$44)-ROW(Januari!$L$6)+1),ROW(H6))))} -> Pembuatan CAP Dinas Baru Untuk bendahara | J9: {=IF($A9="","",INDEX(Januari!K$6:K$44,SMALL(IF(Januari!$L$6:$L$44=$C$1,ROW(Januari!$L$6:$L$44)-ROW(Januari!$L$6)+1),ROW(I6))))} -> 0
A10: {=IFERROR(INDEX(Januari!B$6:B$44,SMALL(IF(Januari!$L$6:$L$44=$C$1,ROW(Januari!$L$6:$L$44)-ROW(Januari!$L$6)+1),ROW(A7))),"")} -> 46041 | B10: {=IF($A10="","",INDEX(Januari!C$6:C$44,SMALL(IF(Januari!$L$6:$L$44=$C$1,ROW(Januari!$L$6:$L$44)-ROW(Januari!$L$6)+1),ROW(A7))))} -> 18750000 | C10: {=IF($A10="","",INDEX(Januari!D$6:D$44,SMALL(IF(Januari!$L$6:$L$44=$C$1,ROW(Januari!$L$6:$L$44)-ROW(Januari!$L$6)+1),ROW(B7))))} -> 18750000 | D10: {=IF($A10="","",INDEX(Januari!E$6:E$44,SMALL(IF(Januari!$L$6:$L$44=$C$1,ROW(Januari!$L$6:$L$44)-ROW(Januari!$L$6)+1),ROW(C7))))} -> Teras Atiqa | E10: {=IF($A10="","",INDEX(Januari!F$6:F$44,SMALL(IF(Januari!$L$6:$L$44=$C$1,ROW(Januari!$L$6:$L$44)-ROW(Januari!$L$6)+1),ROW(D7))))} -> Yulia | F10: {=IF($A10="","",INDEX(Januari!G$6:G$44,SMALL(IF(Januari!$L$6:$L$44=$C$1,ROW(Januari!$L$6:$L$44)-ROW(Januari!$L$6)+1),ROW(E7))))} -> Vivi | G10: {=IF($A10="","",INDEX(Januari!H$6:H$44,SMALL(IF(Januari!$L$6:$L$44=$C$1,ROW(Januari!$L$6:$L$44)-ROW(Januari!$L$6)+1),ROW(F7))))} -> Pagi | H10: {=IF($A10="","",INDEX(Januari!I$6:I$44,SMALL(IF(Januari!$L$6:$L$44=$C$1,ROW(Januari!$L$6:$L$44)-ROW(Januari!$L$6)+1),ROW(G7))))} -> Aula SMK Negeri 2 Kota Ternate | I10: {=IF($A10="","",INDEX(Januari!J$6:J$44,SMALL(IF(Januari!$L$6:$L$44=$C$1,ROW(Januari!$L$6:$L$44)-ROW(Januari!$L$6)+1),ROW(H7))))} -> Kegiatan Peningkatan Kompetensi literasi digital dan Pemahaman Artificial Inteligence (AI) | J10: {=IF($A10="","",INDEX(Januari!K$6:K$44,SMALL(IF(Januari!$L$6:$L$44=$C$1,ROW(Januari!$L$6:$L$44)-ROW(Januari!$L$6)+1),ROW(I7))))} -> 0
A11: {=IFERROR(INDEX(Januari!B$6:B$44,SMALL(IF(Januari!$L$6:$L$44=$C$1,ROW(Januari!$L$6:$L$44)-ROW(Januari!$L$6)+1),ROW(A8))),"")} -> 46042 | B11: {=IF($A11="","",INDEX(Januari!C$6:C$44,SMALL(IF(Januari!$L$6:$L$44=$C$1,ROW(Januari!$L$6:$L$44)-ROW(Januari!$L$6)+1),ROW(A8))))} -> 18750000 | C11: {=IF($A11="","",INDEX(Januari!D$6:D$44,SMALL(IF(Januari!$L$6:$L$44=$C$1,ROW(Januari!$L$6:$L$44)-ROW(Januari!$L$6)+1),ROW(B8))))} -> 18750000 | D11: {=IF($A11="","",INDEX(Januari!E$6:E$44,SMALL(IF(Januari!$L$6:$L$44=$C$1,ROW(Januari!$L$6:$L$44)-ROW(Januari!$L$6)+1),ROW(C8))))} -> Teras Atiqa | E11: {=IF($A11="","",INDEX(Januari!F$6:F$44,SMALL(IF(Januari!$L$6:$L$44=$C$1,ROW(Januari!$L$6:$L$44)-ROW(Januari!$L$6)+1),ROW(D8))))} -> Yulia | F11: {=IF($A11="","",INDEX(Januari!G$6:G$44,SMALL(IF(Januari!$L$6:$L$44=$C$1,ROW(Januari!$L$6:$L$44)-ROW(Januari!$L$6)+1),ROW(E8))))} -> Vivi | G11: {=IF($A11="","",INDEX(Januari!H$6:H$44,SMALL(IF(Januari!$L$6:$L$44=$C$1,ROW(Januari!$L$6:$L$44)-ROW(Januari!$L$6)+1),ROW(F8))))} -> Pagi | H11: {=IF($A11="","",INDEX(Januari!I$6:I$44,SMALL(IF(Januari!$L$6:$L$44=$C$1,ROW(Januari!$L$6:$L$44)-ROW(Januari!$L$6)+1),ROW(G8))))} -> Aula SMK Negeri 2 Kota Ternate | I11: {=IF($A11="","",INDEX(Januari!J$6:J$44,SMALL(IF(Januari!$L$6:$L$44=$C$1,ROW(Januari!$L$6:$L$44)-ROW(Januari!$L$6)+1),ROW(H8))))} -> Kegiatan Peningkatan Kompetensi literasi digital dan Pemahaman Artificial Inteligence (AI) | J11: {=IF($A11="","",INDEX(Januari!K$6:K$44,SMALL(IF(Januari!$L$6:$L$44=$C$1,ROW(Januari!$L$6:$L$44)-ROW(Januari!$L$6)+1),ROW(I8))))} -> 0
A12: {=IFERROR(INDEX(Januari!B$6:B$44,SMALL(IF(Januari!$L$6:$L$44=$C$1,ROW(Januari!$L$6:$L$44)-ROW(Januari!$L$6)+1),ROW(A9))),"")} -> 46043 | B12: {=IF($A12="","",INDEX(Januari!C$6:C$44,SMALL(IF(Januari!$L$6:$L$44=$C$1,ROW(Januari!$L$6:$L$44)-ROW(Januari!$L$6)+1),ROW(A9))))} -> 1200000 | C12: {=IF($A12="","",INDEX(Januari!D$6:D$44,SMALL(IF(Januari!$L$6:$L$44=$C$1,ROW(Januari!$L$6:$L$44)-ROW(Januari!$L$6)+1),ROW(B9))))} -> 1200000 | D12: {=IF($A12="","",INDEX(Januari!E$6:E$44,SMALL(IF(Januari!$L$6:$L$44=$C$1,ROW(Januari!$L$6:$L$44)-ROW(Januari!$L$6)+1),ROW(C9))))} -> Teluk Persia 2 (Canox) | E12: {=IF($A12="","",INDEX(Januari!F$6:F$44,SMALL(IF(Januari!$L$6:$L$44=$C$1,ROW(Januari!$L$6:$L$44)-ROW(Januari!$L$6)+1),ROW(D9))))} -> Yulia | F12: {=IF($A12="","",INDEX(Januari!G$6:G$44,SMALL(IF(Januari!$L$6:$L$44=$C$1,ROW(Januari!$L$6:$L$44)-ROW(Januari!$L$6)+1),ROW(E9))))} -> Vivi | G12: {=IF($A12="","",INDEX(Januari!H$6:H$44,SMALL(IF(Januari!$L$6:$L$44=$C$1,ROW(Januari!$L$6:$L$44)-ROW(Januari!$L$6)+1),ROW(F9))))} -> Pagi | H12: {=IF($A12="","",INDEX(Januari!I$6:I$44,SMALL(IF(Januari!$L$6:$L$44=$C$1,ROW(Januari!$L$6:$L$44)-ROW(Januari!$L$6)+1),ROW(G9))))} -> Sofifi, Pelabuhan Spead Sofifi | I12: {=IF($A12="","",INDEX(Januari!J$6:J$44,SMALL(IF(Januari!$L$6:$L$44=$C$1,ROW(Januari!$L$6:$L$44)-ROW(Januari!$L$6)+1),ROW(H9))))} -> Ke Kantor | J12: {=IF($A12="","",INDEX(Januari!K$6:K$44,SMALL(IF(Januari!$L$6:$L$44=$C$1,ROW(Januari!$L$6:$L$44)-ROW(Januari!$L$6)+1),ROW(I9))))} -> 0
A13: {=IFERROR(INDEX(Januari!B$6:B$44,SMALL(IF(Januari!$L$6:$L$44=$C$1,ROW(Januari!$L$6:$L$44)-ROW(Januari!$L$6)+1),ROW(A10))),"")} -> 46043 | B13: {=IF($A13="","",INDEX(Januari!C$6:C$44,SMALL(IF(Januari!$L$6:$L$44=$C$1,ROW(Januari!$L$6:$L$44)-ROW(Januari!$L$6)+1),ROW(A10))))} -> 700000 | C13: {=IF($A13="","",INDEX(Januari!D$6:D$44,SMALL(IF(Januari!$L$6:$L$44=$C$1,ROW(Januari!$L$6:$L$44)-ROW(Januari!$L$6)+1),ROW(B10))))} -> 700000 | D13: {=IF($A13="","",INDEX(Januari!E$6:E$44,SMALL(IF(Januari!$L$6:$L$44=$C$1,ROW(Januari!$L$6:$L$44)-ROW(Januari!$L$6)+1),ROW(C10))))} -> Teluk Persia 2 (Canox) | E13: {=IF($A13="","",INDEX(Januari!F$6:F$44,SMALL(IF(Januari!$L$6:$L$44=$C$1,ROW(Januari!$L$6:$L$44)-ROW(Januari!$L$6)+1),ROW(D10))))} -> Yulia | F13: {=IF($A13="","",INDEX(Januari!G$6:G$44,SMALL(IF(Januari!$L$6:$L$44=$C$1,ROW(Januari!$L$6:$L$44)-ROW(Januari!$L$6)+1),ROW(E10))))} -> Vivi | G13: {=IF($A13="","",INDEX(Januari!H$6:H$44,SMALL(IF(Januari!$L$6:$L$44=$C$1,ROW(Januari!$L$6:$L$44)-ROW(Januari!$L$6)+1),ROW(F10))))} -> Pagi | H13: {=IF($A13="","",INDEX(Januari!I$6:I$44,SMALL(IF(Januari!$L$6:$L$44=$C$1,ROW(Januari!$L$6:$L$44)-ROW(Januari!$L$6)+1),ROW(G10))))} -> Sofifi, Pelabuhan Spead Sofifi | I13: {=IF($A13="","",INDEX(Januari!J$6:J$44,SMALL(IF(Januari!$L$6:$L$44=$C$1,ROW(Januari!$L$6:$L$44)-ROW(Januari!$L$6)+1),ROW(H10))))} -> pulang batal | J13: {=IF($A13="","",INDEX(Januari!K$6:K$44,SMALL(IF(Januari!$L$6:$L$44=$C$1,ROW(Januari!$L$6:$L$44)-ROW(Januari!$L$6)+1),ROW(I10))))} -> 0
A14: {=IFERROR(INDEX(Januari!B$6:B$44,SMALL(IF(Januari!$L$6:$L$44=$C$1,ROW(Januari!$L$6:$L$44)-ROW(Januari!$L$6)+1),ROW(A11))),"")} -> 46043 | B14: {=IF($A14="","",INDEX(Januari!C$6:C$44,SMALL(IF(Januari!$L$6:$L$44=$C$1,ROW(Januari!$L$6:$L$44)-ROW(Januari!$L$6)+1),ROW(A11))))} -> 3563400 | C14: {=IF($A14="","",INDEX(Januari!D$6:D$44,SMALL(IF(Januari!$L$6:$L$44=$C$1,ROW(Januari!$L$6:$L$44)-ROW(Januari!$L$6)+1),ROW(B11))))} -> 3563400 | D14: {=IF($A14="","",INDEX(Januari!E$6:E$44,SMALL(IF(Januari!$L$6:$L$44=$C$1,ROW(Januari!$L$6:$L$44)-ROW(Januari!$L$6)+1),ROW(C11))))} -> Yulia Travel | E14: {=IF($A14="","",INDEX(Januari!F$6:F$44,SMALL(IF(Januari!$L$6:$L$44=$C$1,ROW(Januari!$L$6:$L$44)-ROW(Januari!$L$6)+1),ROW(D11))))} -> Yulia | F14: {=IF($A14="","",INDEX(Januari!G$6:G$44,SMALL(IF(Januari!$L$6:$L$44=$C$1,ROW(Januari!$L$6:$L$44)-ROW(Januari!$L$6)+1),ROW(E11))))} -> Vivi | G14: {=IF($A14="","",INDEX(Januari!H$6:H$44,SMALL(IF(Januari!$L$6:$L$44=$C$1,ROW(Januari!$L$6:$L$44)-ROW(Januari!$L$6)+1),ROW(F11))))} -> Malam | H14: {=IF($A14="","",INDEX(Januari!I$6:I$44,SMALL(IF(Januari!$L$6:$L$44=$C$1,ROW(Januari!$L$6:$L$44)-ROW(Januari!$L$6)+1),ROW(G11))))} -> Ternate | I14: {=IF($A14="","",INDEX(Januari!J$6:J$44,SMALL(IF(Januari!$L$6:$L$44=$C$1,ROW(Januari!$L$6:$L$44)-ROW(Januari!$L$6)+1),ROW(H11))))} -> Perjadin Pergi | J14: {=IF($A14="","",INDEX(Januari!K$6:K$44,SMALL(IF(Januari!$L$6:$L$44=$C$1,ROW(Januari!$L$6:$L$44)-ROW(Januari!$L$6)+1),ROW(I11))))} -> Abubakar Hi. Abdullah, S.pd., Msi
A15: {=IFERROR(INDEX(Januari!B$6:B$44,SMALL(IF(Januari!$L$6:$L$44=$C$1,ROW(Januari!$L$6:$L$44)-ROW(Januari!$L$6)+1),ROW(A12))),"")} -> 0 | B15: {=IF($A15="","",INDEX(Januari!C$6:C$44,SMALL(IF(Januari!$L$6:$L$44=$C$1,ROW(Januari!$L$6:$L$44)-ROW(Januari!$L$6)+1),ROW(A12))))} -> 2072095 | C15: {=IF($A15="","",INDEX(Januari!D$6:D$44,SMALL(IF(Januari!$L$6:$L$44=$C$1,ROW(Januari!$L$6:$L$44)-ROW(Januari!$L$6)+1),ROW(B12))))} -> 700000 | D15: {=IF($A15="","",INDEX(Januari!E$6:E$44,SMALL(IF(Januari!$L$6:$L$44=$C$1,ROW(Januari!$L$6:$L$44)-ROW(Januari!$L$6)+1),ROW(C12))))} -> 0 | E15: {=IF($A15="","",INDEX(Januari!F$6:F$44,SMALL(IF(Januari!$L$6:$L$44=$C$1,ROW(Januari!$L$6:$L$44)-ROW(Januari!$L$6)+1),ROW(D12))))} -> 0 | F15: {=IF($A15="","",INDEX(Januari!G$6:G$44,SMALL(IF(Januari!$L$6:$L$44=$C$1,ROW(Januari!$L$6:$L$44)-ROW(Januari!$L$6)+1),ROW(E12))))} -> 0 | G15: {=IF($A15="","",INDEX(Januari!H$6:H$44,SMALL(IF(Januari!$L$6:$L$44=$C$1,ROW(Januari!$L$6:$L$44)-ROW(Januari!$L$6)+1),ROW(F12))))} -> 0 | H15: {=IF($A15="","",INDEX(Januari!I$6:I$44,SMALL(IF(Januari!$L$6:$L$44=$C$1,ROW(Januari!$L$6:$L$44)-ROW(Januari!$L$6)+1),ROW(G12))))} -> 0 | I15: {=IF($A15="","",INDEX(Januari!J$6:J$44,SMALL(IF(Januari!$L$6:$L$44=$C$1,ROW(Januari!$L$6:$L$44)-ROW(Januari!$L$6)+1),ROW(H12))))} -> Reschedule 26 januari 2026 | J15: {=IF($A15="","",INDEX(Januari!K$6:K$44,SMALL(IF(Januari!$L$6:$L$44=$C$1,ROW(Januari!$L$6:$L$44)-ROW(Januari!$L$6)+1),ROW(I12))))} -> 0
... A56: {=IFERROR(INDEX(Januari!B$6:B$44,SMALL(IF(Januari!$L$6:$L$44=$C$1,ROW(Januari!$L$6:$L$44)-ROW(Januari!$L$6)+1),ROW(A53))),"")} | B56: {=IF($A56="","",INDEX(Januari!C$6:C$44,SMALL(IF(Januari!$L$6:$L$44=$C$1,ROW(Januari!$L$6:$L$44)-ROW(Januari!$L$6)+1),ROW(A53))))} | C56: {=IF($A56="","",INDEX(Januari!D$6:D$44,SMALL(IF(Januari!$L$6:$L$44=$C$1,ROW(Januari!$L$6:$L$44)-ROW(Januari!$L$6)+1),ROW(B53))))} | D56: {=IF($A56="","",INDEX(Januari!E$6:E$44,SMALL(IF(Januari!$L$6:$L$44=$C$1,ROW(Januari!$L$6:$L$44)-ROW(Januari!$L$6)+1),ROW(C53))))} | E56: {=IF($A56="","",INDEX(Januari!F$6:F$44,SMALL(IF(Januari!$L$6:$L$44=$C$1,ROW(Januari!$L$6:$L$44)-ROW(Januari!$L$6)+1),ROW(D53))))} | F56: {=IF($A56="","",INDEX(Januari!G$6:G$44,SMALL(IF(Januari!$L$6:$L$44=$C$1,ROW(Januari!$L$6:$L$44)-ROW(Januari!$L$6)+1),ROW(E53))))} | G56: {=IF($A56="","",INDEX(Januari!H$6:H$44,SMALL(IF(Januari!$L$6:$L$44=$C$1,ROW(Januari!$L$6:$L$44)-ROW(Januari!$L$6)+1),ROW(F53))))} | H56: {=IF($A56="","",INDEX(Januari!I$6:I$44,SMALL(IF(Januari!$L$6:$L$44=$C$1,ROW(Januari!$L$6:$L$44)-ROW(Januari!$L$6)+1),ROW(G53))))} | I56: {=IF($A56="","",INDEX(Januari!J$6:J$44,SMALL(IF(Januari!$L$6:$L$44=$C$1,ROW(Januari!$L$6:$L$44)-ROW(Januari!$L$6)+1),ROW(H53))))} | J56: {=IF($A56="","",INDEX(Januari!K$6:K$44,SMALL(IF(Januari!$L$6:$L$44=$C$1,ROW(Januari!$L$6:$L$44)-ROW(Januari!$L$6)+1),ROW(I53))))}
A57: {=IFERROR(INDEX(Januari!B$6:B$44,SMALL(IF(Januari!$L$6:$L$44=$C$1,ROW(Januari!$L$6:$L$44)-ROW(Januari!$L$6)+1),ROW(A54))),"")} | C57: {=IF($A57="","",INDEX(Januari!D$6:D$44,SMALL(IF(Januari!$L$6:$L$44=$C$1,ROW(Januari!$L$6:$L$44)-ROW(Januari!$L$6)+1),ROW(B54))))} | D57: {=IF($A57="","",INDEX(Januari!E$6:E$44,SMALL(IF(Januari!$L$6:$L$44=$C$1,ROW(Januari!$L$6:$L$44)-ROW(Januari!$L$6)+1),ROW(C54))))} | E57: {=IF($A57="","",INDEX(Januari!F$6:F$44,SMALL(IF(Januari!$L$6:$L$44=$C$1,ROW(Januari!$L$6:$L$44)-ROW(Januari!$L$6)+1),ROW(D54))))} | F57: {=IF($A57="","",INDEX(Januari!G$6:G$44,SMALL(IF(Januari!$L$6:$L$44=$C$1,ROW(Januari!$L$6:$L$44)-ROW(Januari!$L$6)+1),ROW(E54))))} | G57: {=IF($A57="","",INDEX(Januari!H$6:H$44,SMALL(IF(Januari!$L$6:$L$44=$C$1,ROW(Januari!$L$6:$L$44)-ROW(Januari!$L$6)+1),ROW(F54))))} | H57: {=IF($A57="","",INDEX(Januari!I$6:I$44,SMALL(IF(Januari!$L$6:$L$44=$C$1,ROW(Januari!$L$6:$L$44)-ROW(Januari!$L$6)+1),ROW(G54))))} | I57: {=IF($A57="","",INDEX(Januari!J$6:J$44,SMALL(IF(Januari!$L$6:$L$44=$C$1,ROW(Januari!$L$6:$L$44)-ROW(Januari!$L$6)+1),ROW(H54))))} | J57: {=IF($A57="","",INDEX(Januari!K$6:K$44,SMALL(IF(Januari!$L$6:$L$44=$C$1,ROW(Januari!$L$6:$L$44)-ROW(Januari!$L$6)+1),ROW(I54))))}
A58: {=IFERROR(INDEX(Januari!B$6:B$44,SMALL(IF(Januari!$L$6:$L$44=$C$1,ROW(Januari!$L$6:$L$44)-ROW(Januari!$L$6)+1),ROW(A55))),"")} | C58: {=IF($A58="","",INDEX(Januari!D$6:D$44,SMALL(IF(Januari!$L$6:$L$44=$C$1,ROW(Januari!$L$6:$L$44)-ROW(Januari!$L$6)+1),ROW(B55))))} | D58: {=IF($A58="","",INDEX(Januari!E$6:E$44,SMALL(IF(Januari!$L$6:$L$44=$C$1,ROW(Januari!$L$6:$L$44)-ROW(Januari!$L$6)+1),ROW(C55))))} | E58: {=IF($A58="","",INDEX(Januari!F$6:F$44,SMALL(IF(Januari!$L$6:$L$44=$C$1,ROW(Januari!$L$6:$L$44)-ROW(Januari!$L$6)+1),ROW(D55))))} | F58: {=IF($A58="","",INDEX(Januari!G$6:G$44,SMALL(IF(Januari!$L$6:$L$44=$C$1,ROW(Januari!$L$6:$L$44)-ROW(Januari!$L$6)+1),ROW(E55))))} | G58: {=IF($A58="","",INDEX(Januari!H$6:H$44,SMALL(IF(Januari!$L$6:$L$44=$C$1,ROW(Januari!$L$6:$L$44)-ROW(Januari!$L$6)+1),ROW(F55))))} | H58: {=IF($A58="","",INDEX(Januari!I$6:I$44,SMALL(IF(Januari!$L$6:$L$44=$C$1,ROW(Januari!$L$6:$L$44)-ROW(Januari!$L$6)+1),ROW(G55))))} | I58: {=IF($A58="","",INDEX(Januari!J$6:J$44,SMALL(IF(Januari!$L$6:$L$44=$C$1,ROW(Januari!$L$6:$L$44)-ROW(Januari!$L$6)+1),ROW(H55))))} | J58: {=IF($A58="","",INDEX(Januari!K$6:K$44,SMALL(IF(Januari!$L$6:$L$44=$C$1,ROW(Januari!$L$6:$L$44)-ROW(Januari!$L$6)+1),ROW(I55))))}
A59: {=IFERROR(INDEX(Januari!B$6:B$44,SMALL(IF(Januari!$L$6:$L$44=$C$1,ROW(Januari!$L$6:$L$44)-ROW(Januari!$L$6)+1),ROW(A56))),"")} | C59: {=IF($A59="","",INDEX(Januari!D$6:D$44,SMALL(IF(Januari!$L$6:$L$44=$C$1,ROW(Januari!$L$6:$L$44)-ROW(Januari!$L$6)+1),ROW(B56))))} | D59: {=IF($A59="","",INDEX(Januari!E$6:E$44,SMALL(IF(Januari!$L$6:$L$44=$C$1,ROW(Januari!$L$6:$L$44)-ROW(Januari!$L$6)+1),ROW(C56))))} | E59: {=IF($A59="","",INDEX(Januari!F$6:F$44,SMALL(IF(Januari!$L$6:$L$44=$C$1,ROW(Januari!$L$6:$L$44)-ROW(Januari!$L$6)+1),ROW(D56))))} | F59: {=IF($A59="","",INDEX(Januari!G$6:G$44,SMALL(IF(Januari!$L$6:$L$44=$C$1,ROW(Januari!$L$6:$L$44)-ROW(Januari!$L$6)+1),ROW(E56))))} | G59: {=IF($A59="","",INDEX(Januari!H$6:H$44,SMALL(IF(Januari!$L$6:$L$44=$C$1,ROW(Januari!$L$6:$L$44)-ROW(Januari!$L$6)+1),ROW(F56))))} | H59: {=IF($A59="","",INDEX(Januari!I$6:I$44,SMALL(IF(Januari!$L$6:$L$44=$C$1,ROW(Januari!$L$6:$L$44)-ROW(Januari!$L$6)+1),ROW(G56))))} | I59: {=IF($A59="","",INDEX(Januari!J$6:J$44,SMALL(IF(Januari!$L$6:$L$44=$C$1,ROW(Januari!$L$6:$L$44)-ROW(Januari!$L$6)+1),ROW(H56))))} | J59: {=IF($A59="","",INDEX(Januari!K$6:K$44,SMALL(IF(Januari!$L$6:$L$44=$C$1,ROW(Januari!$L$6:$L$44)-ROW(Januari!$L$6)+1),ROW(I56))))}
A60: {=IFERROR(INDEX(Januari!B$6:B$44,SMALL(IF(Januari!$L$6:$L$44=$C$1,ROW(Januari!$L$6:$L$44)-ROW(Januari!$L$6)+1),ROW(A57))),"")} | C60: {=IF($A60="","",INDEX(Januari!D$6:D$44,SMALL(IF(Januari!$L$6:$L$44=$C$1,ROW(Januari!$L$6:$L$44)-ROW(Januari!$L$6)+1),ROW(B57))))} | D60: {=IF($A60="","",INDEX(Januari!E$6:E$44,SMALL(IF(Januari!$L$6:$L$44=$C$1,ROW(Januari!$L$6:$L$44)-ROW(Januari!$L$6)+1),ROW(C57))))} | E60: {=IF($A60="","",INDEX(Januari!F$6:F$44,SMALL(IF(Januari!$L$6:$L$44=$C$1,ROW(Januari!$L$6:$L$44)-ROW(Januari!$L$6)+1),ROW(D57))))} | F60: {=IF($A60="","",INDEX(Januari!G$6:G$44,SMALL(IF(Januari!$L$6:$L$44=$C$1,ROW(Januari!$L$6:$L$44)-ROW(Januari!$L$6)+1),ROW(E57))))} | G60: {=IF($A60="","",INDEX(Januari!H$6:H$44,SMALL(IF(Januari!$L$6:$L$44=$C$1,ROW(Januari!$L$6:$L$44)-ROW(Januari!$L$6)+1),ROW(F57))))} | H60: {=IF($A60="","",INDEX(Januari!I$6:I$44,SMALL(IF(Januari!$L$6:$L$44=$C$1,ROW(Januari!$L$6:$L$44)-ROW(Januari!$L$6)+1),ROW(G57))))} | I60: {=IF($A60="","",INDEX(Januari!J$6:J$44,SMALL(IF(Januari!$L$6:$L$44=$C$1,ROW(Januari!$L$6:$L$44)-ROW(Januari!$L$6)+1),ROW(H57))))} | J60: {=IF($A60="","",INDEX(Januari!K$6:K$44,SMALL(IF(Januari!$L$6:$L$44=$C$1,ROW(Januari!$L$6:$L$44)-ROW(Januari!$L$6)+1),ROW(I57))))}
A61: {=IFERROR(INDEX(Januari!B$6:B$44,SMALL(IF(Januari!$L$6:$L$44=$C$1,ROW(Januari!$L$6:$L$44)-ROW(Januari!$L$6)+1),ROW(A58))),"")} | C61: {=IF($A61="","",INDEX(Januari!D$6:D$44,SMALL(IF(Januari!$L$6:$L$44=$C$1,ROW(Januari!$L$6:$L$44)-ROW(Januari!$L$6)+1),ROW(B58))))} | D61: {=IF($A61="","",INDEX(Januari!E$6:E$44,SMALL(IF(Januari!$L$6:$L$44=$C$1,ROW(Januari!$L$6:$L$44)-ROW(Januari!$L$6)+1),ROW(C58))))} | E61: {=IF($A61="","",INDEX(Januari!F$6:F$44,SMALL(IF(Januari!$L$6:$L$44=$C$1,ROW(Januari!$L$6:$L$44)-ROW(Januari!$L$6)+1),ROW(D58))))} | F61: {=IF($A61="","",INDEX(Januari!G$6:G$44,SMALL(IF(Januari!$L$6:$L$44=$C$1,ROW(Januari!$L$6:$L$44)-ROW(Januari!$L$6)+1),ROW(E58))))} | G61: {=IF($A61="","",INDEX(Januari!H$6:H$44,SMALL(IF(Januari!$L$6:$L$44=$C$1,ROW(Januari!$L$6:$L$44)-ROW(Januari!$L$6)+1),ROW(F58))))} | H61: {=IF($A61="","",INDEX(Januari!I$6:I$44,SMALL(IF(Januari!$L$6:$L$44=$C$1,ROW(Januari!$L$6:$L$44)-ROW(Januari!$L$6)+1),ROW(G58))))} | I61: {=IF($A61="","",INDEX(Januari!J$6:J$44,SMALL(IF(Januari!$L$6:$L$44=$C$1,ROW(Januari!$L$6:$L$44)-ROW(Januari!$L$6)+1),ROW(H58))))} | J61: {=IF($A61="","",INDEX(Januari!K$6:K$44,SMALL(IF(Januari!$L$6:$L$44=$C$1,ROW(Januari!$L$6:$L$44)-ROW(Januari!$L$6)+1),ROW(I58))))}
A62: {=IFERROR(INDEX(Januari!B$6:B$44,SMALL(IF(Januari!$L$6:$L$44=$C$1,ROW(Januari!$L$6:$L$44)-ROW(Januari!$L$6)+1),ROW(A59))),"")} | C62: {=IF($A62="","",INDEX(Januari!D$6:D$44,SMALL(IF(Januari!$L$6:$L$44=$C$1,ROW(Januari!$L$6:$L$44)-ROW(Januari!$L$6)+1),ROW(B59))))} | D62: {=IF($A62="","",INDEX(Januari!E$6:E$44,SMALL(IF(Januari!$L$6:$L$44=$C$1,ROW(Januari!$L$6:$L$44)-ROW(Januari!$L$6)+1),ROW(C59))))} | E62: {=IF($A62="","",INDEX(Januari!F$6:F$44,SMALL(IF(Januari!$L$6:$L$44=$C$1,ROW(Januari!$L$6:$L$44)-ROW(Januari!$L$6)+1),ROW(D59))))} | F62: {=IF($A62="","",INDEX(Januari!G$6:G$44,SMALL(IF(Januari!$L$6:$L$44=$C$1,ROW(Januari!$L$6:$L$44)-ROW(Januari!$L$6)+1),ROW(E59))))} | G62: {=IF($A62="","",INDEX(Januari!H$6:H$44,SMALL(IF(Januari!$L$6:$L$44=$C$1,ROW(Januari!$L$6:$L$44)-ROW(Januari!$L$6)+1),ROW(F59))))} | H62: {=IF($A62="","",INDEX(Januari!I$6:I$44,SMALL(IF(Januari!$L$6:$L$44=$C$1,ROW(Januari!$L$6:$L$44)-ROW(Januari!$L$6)+1),ROW(G59))))} | I62: {=IF($A62="","",INDEX(Januari!J$6:J$44,SMALL(IF(Januari!$L$6:$L$44=$C$1,ROW(Januari!$L$6:$L$44)-ROW(Januari!$L$6)+1),ROW(H59))))} | J62: {=IF($A62="","",INDEX(Januari!K$6:K$44,SMALL(IF(Januari!$L$6:$L$44=$C$1,ROW(Januari!$L$6:$L$44)-ROW(Januari!$L$6)+1),ROW(I59))))}
A63: {=IFERROR(INDEX(Januari!B$6:B$44,SMALL(IF(Januari!$L$6:$L$44=$C$1,ROW(Januari!$L$6:$L$44)-ROW(Januari!$L$6)+1),ROW(A60))),"")} | C63: {=IF($A63="","",INDEX(Januari!D$6:D$44,SMALL(IF(Januari!$L$6:$L$44=$C$1,ROW(Januari!$L$6:$L$44)-ROW(Januari!$L$6)+1),ROW(B60))))} | D63: {=IF($A63="","",INDEX(Januari!E$6:E$44,SMALL(IF(Januari!$L$6:$L$44=$C$1,ROW(Januari!$L$6:$L$44)-ROW(Januari!$L$6)+1),ROW(C60))))} | E63: {=IF($A63="","",INDEX(Januari!F$6:F$44,SMALL(IF(Januari!$L$6:$L$44=$C$1,ROW(Januari!$L$6:$L$44)-ROW(Januari!$L$6)+1),ROW(D60))))} | F63: {=IF($A63="","",INDEX(Januari!G$6:G$44,SMALL(IF(Januari!$L$6:$L$44=$C$1,ROW(Januari!$L$6:$L$44)-ROW(Januari!$L$6)+1),ROW(E60))))} | G63: {=IF($A63="","",INDEX(Januari!H$6:H$44,SMALL(IF(Januari!$L$6:$L$44=$C$1,ROW(Januari!$L$6:$L$44)-ROW(Januari!$L$6)+1),ROW(F60))))} | H63: {=IF($A63="","",INDEX(Januari!I$6:I$44,SMALL(IF(Januari!$L$6:$L$44=$C$1,ROW(Januari!$L$6:$L$44)-ROW(Januari!$L$6)+1),ROW(G60))))} | I63: {=IF($A63="","",INDEX(Januari!J$6:J$44,SMALL(IF(Januari!$L$6:$L$44=$C$1,ROW(Januari!$L$6:$L$44)-ROW(Januari!$L$6)+1),ROW(H60))))} | J63: {=IF($A63="","",INDEX(Januari!K$6:K$44,SMALL(IF(Januari!$L$6:$L$44=$C$1,ROW(Januari!$L$6:$L$44)-ROW(Januari!$L$6)+1),ROW(I60))))}
A64: {=IFERROR(INDEX(Januari!B$6:B$44,SMALL(IF(Januari!$L$6:$L$44=$C$1,ROW(Januari!$L$6:$L$44)-ROW(Januari!$L$6)+1),ROW(A61))),"")} | C64: {=IF($A64="","",INDEX(Januari!D$6:D$44,SMALL(IF(Januari!$L$6:$L$44=$C$1,ROW(Januari!$L$6:$L$44)-ROW(Januari!$L$6)+1),ROW(B61))))} | D64: {=IF($A64="","",INDEX(Januari!E$6:E$44,SMALL(IF(Januari!$L$6:$L$44=$C$1,ROW(Januari!$L$6:$L$44)-ROW(Januari!$L$6)+1),ROW(C61))))} | E64: {=IF($A64="","",INDEX(Januari!F$6:F$44,SMALL(IF(Januari!$L$6:$L$44=$C$1,ROW(Januari!$L$6:$L$44)-ROW(Januari!$L$6)+1),ROW(D61))))} | F64: {=IF($A64="","",INDEX(Januari!G$6:G$44,SMALL(IF(Januari!$L$6:$L$44=$C$1,ROW(Januari!$L$6:$L$44)-ROW(Januari!$L$6)+1),ROW(E61))))} | G64: {=IF($A64="","",INDEX(Januari!H$6:H$44,SMALL(IF(Januari!$L$6:$L$44=$C$1,ROW(Januari!$L$6:$L$44)-ROW(Januari!$L$6)+1),ROW(F61))))} | H64: {=IF($A64="","",INDEX(Januari!I$6:I$44,SMALL(IF(Januari!$L$6:$L$44=$C$1,ROW(Januari!$L$6:$L$44)-ROW(Januari!$L$6)+1),ROW(G61))))} | I64: {=IF($A64="","",INDEX(Januari!J$6:J$44,SMALL(IF(Januari!$L$6:$L$44=$C$1,ROW(Januari!$L$6:$L$44)-ROW(Januari!$L$6)+1),ROW(H61))))} | J64: {=IF($A64="","",INDEX(Januari!K$6:K$44,SMALL(IF(Januari!$L$6:$L$44=$C$1,ROW(Januari!$L$6:$L$44)-ROW(Januari!$L$6)+1),ROW(I61))))}
A65: {=IFERROR(INDEX(Januari!B$6:B$44,SMALL(IF(Januari!$L$6:$L$44=$C$1,ROW(Januari!$L$6:$L$44)-ROW(Januari!$L$6)+1),ROW(A62))),"")} | C65: {=IF($A65="","",INDEX(Januari!D$6:D$44,SMALL(IF(Januari!$L$6:$L$44=$C$1,ROW(Januari!$L$6:$L$44)-ROW(Januari!$L$6)+1),ROW(B62))))} | D65: {=IF($A65="","",INDEX(Januari!E$6:E$44,SMALL(IF(Januari!$L$6:$L$44=$C$1,ROW(Januari!$L$6:$L$44)-ROW(Januari!$L$6)+1),ROW(C62))))} | E65: {=IF($A65="","",INDEX(Januari!F$6:F$44,SMALL(IF(Januari!$L$6:$L$44=$C$1,ROW(Januari!$L$6:$L$44)-ROW(Januari!$L$6)+1),ROW(D62))))} | F65: {=IF($A65="","",INDEX(Januari!G$6:G$44,SMALL(IF(Januari!$L$6:$L$44=$C$1,ROW(Januari!$L$6:$L$44)-ROW(Januari!$L$6)+1),ROW(E62))))} | G65: {=IF($A65="","",INDEX(Januari!H$6:H$44,SMALL(IF(Januari!$L$6:$L$44=$C$1,ROW(Januari!$L$6:$L$44)-ROW(Januari!$L$6)+1),ROW(F62))))} | H65: {=IF($A65="","",INDEX(Januari!I$6:I$44,SMALL(IF(Januari!$L$6:$L$44=$C$1,ROW(Januari!$L$6:$L$44)-ROW(Januari!$L$6)+1),ROW(G62))))} | I65: {=IF($A65="","",INDEX(Januari!J$6:J$44,SMALL(IF(Januari!$L$6:$L$44=$C$1,ROW(Januari!$L$6:$L$44)-ROW(Januari!$L$6)+1),ROW(H62))))} | J65: {=IF($A65="","",INDEX(Januari!K$6:K$44,SMALL(IF(Januari!$L$6:$L$44=$C$1,ROW(Januari!$L$6:$L$44)-ROW(Januari!$L$6)+1),ROW(I62))))}
A66: {=IFERROR(INDEX(Januari!B$6:B$44,SMALL(IF(Januari!$L$6:$L$44=$C$1,ROW(Januari!$L$6:$L$44)-ROW(Januari!$L$6)+1),ROW(A63))),"")} | C66: {=IF($A66="","",INDEX(Januari!D$6:D$44,SMALL(IF(Januari!$L$6:$L$44=$C$1,ROW(Januari!$L$6:$L$44)-ROW(Januari!$L$6)+1),ROW(B63))))} | D66: {=IF($A66="","",INDEX(Januari!E$6:E$44,SMALL(IF(Januari!$L$6:$L$44=$C$1,ROW(Januari!$L$6:$L$44)-ROW(Januari!$L$6)+1),ROW(C63))))} | E66: {=IF($A66="","",INDEX(Januari!F$6:F$44,SMALL(IF(Januari!$L$6:$L$44=$C$1,ROW(Januari!$L$6:$L$44)-ROW(Januari!$L$6)+1),ROW(D63))))} | F66: {=IF($A66="","",INDEX(Januari!G$6:G$44,SMALL(IF(Januari!$L$6:$L$44=$C$1,ROW(Januari!$L$6:$L$44)-ROW(Januari!$L$6)+1),ROW(E63))))} | G66: {=IF($A66="","",INDEX(Januari!H$6:H$44,SMALL(IF(Januari!$L$6:$L$44=$C$1,ROW(Januari!$L$6:$L$44)-ROW(Januari!$L$6)+1),ROW(F63))))} | H66: {=IF($A66="","",INDEX(Januari!I$6:I$44,SMALL(IF(Januari!$L$6:$L$44=$C$1,ROW(Januari!$L$6:$L$44)-ROW(Januari!$L$6)+1),ROW(G63))))} | I66: {=IF($A66="","",INDEX(Januari!J$6:J$44,SMALL(IF(Januari!$L$6:$L$44=$C$1,ROW(Januari!$L$6:$L$44)-ROW(Januari!$L$6)+1),ROW(H63))))} | J66: {=IF($A66="","",INDEX(Januari!K$6:K$44,SMALL(IF(Januari!$L$6:$L$44=$C$1,ROW(Januari!$L$6:$L$44)-ROW(Januari!$L$6)+1),ROW(I63))))}
A67: {=IFERROR(INDEX(Januari!B$6:B$44,SMALL(IF(Januari!$L$6:$L$44=$C$1,ROW(Januari!$L$6:$L$44)-ROW(Januari!$L$6)+1),ROW(A64))),"")} | C67: {=IF($A67="","",INDEX(Januari!D$6:D$44,SMALL(IF(Januari!$L$6:$L$44=$C$1,ROW(Januari!$L$6:$L$44)-ROW(Januari!$L$6)+1),ROW(B64))))} | D67: {=IF($A67="","",INDEX(Januari!E$6:E$44,SMALL(IF(Januari!$L$6:$L$44=$C$1,ROW(Januari!$L$6:$L$44)-ROW(Januari!$L$6)+1),ROW(C64))))} | E67: {=IF($A67="","",INDEX(Januari!F$6:F$44,SMALL(IF(Januari!$L$6:$L$44=$C$1,ROW(Januari!$L$6:$L$44)-ROW(Januari!$L$6)+1),ROW(D64))))} | F67: {=IF($A67="","",INDEX(Januari!G$6:G$44,SMALL(IF(Januari!$L$6:$L$44=$C$1,ROW(Januari!$L$6:$L$44)-ROW(Januari!$L$6)+1),ROW(E64))))} | G67: {=IF($A67="","",INDEX(Januari!H$6:H$44,SMALL(IF(Januari!$L$6:$L$44=$C$1,ROW(Januari!$L$6:$L$44)-ROW(Januari!$L$6)+1),ROW(F64))))} | H67: {=IF($A67="","",INDEX(Januari!I$6:I$44,SMALL(IF(Januari!$L$6:$L$44=$C$1,ROW(Januari!$L$6:$L$44)-ROW(Januari!$L$6)+1),ROW(G64))))} | I67: {=IF($A67="","",INDEX(Januari!J$6:J$44,SMALL(IF(Januari!$L$6:$L$44=$C$1,ROW(Januari!$L$6:$L$44)-ROW(Januari!$L$6)+1),ROW(H64))))} | J67: {=IF($A67="","",INDEX(Januari!K$6:K$44,SMALL(IF(Januari!$L$6:$L$44=$C$1,ROW(Januari!$L$6:$L$44)-ROW(Januari!$L$6)+1),ROW(I64))))}
A68: {=IFERROR(INDEX(Januari!B$6:B$44,SMALL(IF(Januari!$L$6:$L$44=$C$1,ROW(Januari!$L$6:$L$44)-ROW(Januari!$L$6)+1),ROW(A65))),"")} | C68: {=IF($A68="","",INDEX(Januari!D$6:D$44,SMALL(IF(Januari!$L$6:$L$44=$C$1,ROW(Januari!$L$6:$L$44)-ROW(Januari!$L$6)+1),ROW(B65))))} | D68: {=IF($A68="","",INDEX(Januari!E$6:E$44,SMALL(IF(Januari!$L$6:$L$44=$C$1,ROW(Januari!$L$6:$L$44)-ROW(Januari!$L$6)+1),ROW(C65))))} | E68: {=IF($A68="","",INDEX(Januari!F$6:F$44,SMALL(IF(Januari!$L$6:$L$44=$C$1,ROW(Januari!$L$6:$L$44)-ROW(Januari!$L$6)+1),ROW(D65))))} | F68: {=IF($A68="","",INDEX(Januari!G$6:G$44,SMALL(IF(Januari!$L$6:$L$44=$C$1,ROW(Januari!$L$6:$L$44)-ROW(Januari!$L$6)+1),ROW(E65))))} | G68: {=IF($A68="","",INDEX(Januari!H$6:H$44,SMALL(IF(Januari!$L$6:$L$44=$C$1,ROW(Januari!$L$6:$L$44)-ROW(Januari!$L$6)+1),ROW(F65))))} | H68: {=IF($A68="","",INDEX(Januari!I$6:I$44,SMALL(IF(Januari!$L$6:$L$44=$C$1,ROW(Januari!$L$6:$L$44)-ROW(Januari!$L$6)+1),ROW(G65))))} | I68: {=IF($A68="","",INDEX(Januari!J$6:J$44,SMALL(IF(Januari!$L$6:$L$44=$C$1,ROW(Januari!$L$6:$L$44)-ROW(Januari!$L$6)+1),ROW(H65))))} | J68: {=IF($A68="","",INDEX(Januari!K$6:K$44,SMALL(IF(Januari!$L$6:$L$44=$C$1,ROW(Januari!$L$6:$L$44)-ROW(Januari!$L$6)+1),ROW(I65))))}
... A150: {=IFERROR(INDEX(Januari!B$6:B$44,SMALL(IF(Januari!$L$6:$L$44=$C$1,ROW(Januari!$L$6:$L$44)-ROW(Januari!$L$6)+1),ROW(A147))),"")} | C150: {=IF($A150="","",INDEX(Januari!D$6:D$44,SMALL(IF(Januari!$L$6:$L$44=$C$1,ROW(Januari!$L$6:$L$44)-ROW(Januari!$L$6)+1),ROW(B147))))} | D150: {=IF($A150="","",INDEX(Januari!E$6:E$44,SMALL(IF(Januari!$L$6:$L$44=$C$1,ROW(Januari!$L$6:$L$44)-ROW(Januari!$L$6)+1),ROW(C147))))} | E150: {=IF($A150="","",INDEX(Januari!F$6:F$44,SMALL(IF(Januari!$L$6:$L$44=$C$1,ROW(Januari!$L$6:$L$44)-ROW(Januari!$L$6)+1),ROW(D147))))} | F150: {=IF($A150="","",INDEX(Januari!G$6:G$44,SMALL(IF(Januari!$L$6:$L$44=$C$1,ROW(Januari!$L$6:$L$44)-ROW(Januari!$L$6)+1),ROW(E147))))} | G150: {=IF($A150="","",INDEX(Januari!H$6:H$44,SMALL(IF(Januari!$L$6:$L$44=$C$1,ROW(Januari!$L$6:$L$44)-ROW(Januari!$L$6)+1),ROW(F147))))} | H150: {=IF($A150="","",INDEX(Januari!I$6:I$44,SMALL(IF(Januari!$L$6:$L$44=$C$1,ROW(Januari!$L$6:$L$44)-ROW(Januari!$L$6)+1),ROW(G147))))} | I150: {=IF($A150="","",INDEX(Januari!J$6:J$44,SMALL(IF(Januari!$L$6:$L$44=$C$1,ROW(Januari!$L$6:$L$44)-ROW(Januari!$L$6)+1),ROW(H147))))} | J150: {=IF($A150="","",INDEX(Januari!K$6:K$44,SMALL(IF(Januari!$L$6:$L$44=$C$1,ROW(Januari!$L$6:$L$44)-ROW(Januari!$L$6)+1),ROW(I147))))}
A151: {=IFERROR(INDEX(Januari!B$6:B$44,SMALL(IF(Januari!$L$6:$L$44=$C$1,ROW(Januari!$L$6:$L$44)-ROW(Januari!$L$6)+1),ROW(A148))),"")} | C151: {=IF($A151="","",INDEX(Januari!D$6:D$44,SMALL(IF(Januari!$L$6:$L$44=$C$1,ROW(Januari!$L$6:$L$44)-ROW(Januari!$L$6)+1),ROW(B148))))} | E151: {=IF($A151="","",INDEX(Januari!F$6:F$44,SMALL(IF(Januari!$L$6:$L$44=$C$1,ROW(Januari!$L$6:$L$44)-ROW(Januari!$L$6)+1),ROW(D148))))} | F151: {=IF($A151="","",INDEX(Januari!G$6:G$44,SMALL(IF(Januari!$L$6:$L$44=$C$1,ROW(Januari!$L$6:$L$44)-ROW(Januari!$L$6)+1),ROW(E148))))} | G151: {=IF($A151="","",INDEX(Januari!H$6:H$44,SMALL(IF(Januari!$L$6:$L$44=$C$1,ROW(Januari!$L$6:$L$44)-ROW(Januari!$L$6)+1),ROW(F148))))} | H151: {=IF($A151="","",INDEX(Januari!I$6:I$44,SMALL(IF(Januari!$L$6:$L$44=$C$1,ROW(Januari!$L$6:$L$44)-ROW(Januari!$L$6)+1),ROW(G148))))} | I151: {=IF($A151="","",INDEX(Januari!J$6:J$44,SMALL(IF(Januari!$L$6:$L$44=$C$1,ROW(Januari!$L$6:$L$44)-ROW(Januari!$L$6)+1),ROW(H148))))} | J151: {=IF($A151="","",INDEX(Januari!K$6:K$44,SMALL(IF(Januari!$L$6:$L$44=$C$1,ROW(Januari!$L$6:$L$44)-ROW(Januari!$L$6)+1),ROW(I148))))}

Sheet Februari
A1: LEMBAR KONTROL HUTANG
A2: Periode 01 Februari s/d 28 Februari 2026
A4: No | B4: Hari, Tanggal | C4: Jumlah Nominal yang dikeluarkan | D4: Jumlah yang diterima | E4: Pihak Ke 3 | F4: Petugas Penerima | G4: Pejabat yang ditunjuk sbg Penerima | H4: Waktu Penyerahan | I4: Lokasi Penyerahan | J4: Tujuan/Keperluan | L4: SUMBER DANA | M4: STATUS | N4: NOMINAL BAYAR SEBAGIAN | O4: BUKTI
A6: 1 | B6: 46045 | C6: 1000000 | D6: =C6 -> 1000000 | E6: Pa Ongen | F6: Yulia | G6: Vivi | H6: Sore | I6: Sofifi, Kantor DIKBUD | J6: Pembelian BBM Mobil KADIS di Ternate | K6: Dinota 950.000 | L6: DANSAV UPY | M6: LUNAS
A7: 2 | B7: 46055 | C7: 600000 | D7: =C7 -> 600000 | E7: SPBU Sofifi | F7: Om Wan | G7: Vivi | H7: Pagi | I7: Sofifi, SPBU SOfifi | J7: Pembelian BBM Mobil KADIS di Sofifi | L7: DANSAV UPY | M7: LUNAS
A8: 2 | B8: 46055 | C8: 100000 | D8: =C8 -> 100000 | E8: Pak Iwan | F8: Yulia | G8: Vivi | H8: Pagi | I8: Sofifi, SPBU SOfifi | J8: Ongkos Pak iwan | L8: DANSAV UPY | M8: LUNAS
A9: 4 | B9: 46055 | C9: 1200000 | D9: =C9 -> 1200000 | E9: Teluk Persia 1 | F9: Yulia | G9: Vivi | H9: Pagi | I9: Ternate, Pelabuhan SEMUT | J9: Kantor | L9: DANSAV UPY | M9: LUNAS
A10: 5 | B10: 46055 | C10: 1200000 | D10: =C10 -> 1200000 | E10: Teluk Persia 2 | F10: Yulia | G10: Vivi | H10: Sore | I10: Sofifi, Pelabuhan Spead Sofifi | J10: Kantor | L10: DANSAV UPY | M10: LUNAS
A11: 6 | B11: 46055 | C11: 1000000 | D11: =C11 -> 1000000 | E11: Ayu | F11: Yulia | G11: Vivi | H11: Pagi | I11: Sofifi, Kantor DIKBUD | J11: Makanan Kadis dan kue | L11: DANSAV UPY | M11: LUNAS
A12: 7 | B12: 46055 | C12: 1455000 | D12: =C12 -> 1455000 | E12: Fauzin Pratama | F12: Vivi | G12: Vivi | H12: Pagi | I12: Sofifi, Kantor DIKBUD | J12: ATK | K12: Vivi | L12: VIVI | M12: HUTANG
B13: 46055 | C13: 708000 | D13: =C13 -> 708000 | E13: Pa Ongen | F13: Yulia | G13: Vivi | H13: Pagi | I13: Sofifi, SPBU SOfifi | J13: Pembelian BBM Mobil SEKDIS di Sofifi | K13: Kasih 750.000 | L13: DANSAV UPY | M13: LUNAS
A14: 8 | B14: 46055 | C14: 1555000 | D14: =C14 -> 1555000 | E14: Fauzin Pratama | F14: Vivi | G14: Vivi | H14: Pagi | I14: Sofifi, Kantor DIKBUD | J14: ATK | K14: Vivi | L14: VIVI | M14: HUTANG
A15: 9 | B15: 46056 | C15: 310000 | D15: =C15 -> 310000 | E15: Teras Atiqah | F15: Yulia | G15: Vivi | H15: Pagi | I15: SMK Negeri 1 Ternate | J15: Pembelian Snack Pagi+Minuman | K15: 5 Piring | L15: DANSAV MAKMUR | M15: LUNAS | P15: Pak Makmur
A16: 10 | B16: 46056 | C16: 585000 | D16: =C16 -> 585000 | E16: Teras Atiqah | F16: Yulia | G16: Vivi | H16: Pagi | I16: SMK Negeri 1 Ternate | J16: Pembelian Makan Siang+Minuman | K16: 15 Orang | L16: DANSAV MAKMUR | M16: LUNAS | P16: Pak Makmur
A17: 11 | B17: 46056 | C17: 500000 | D17: =C17 -> 500000 | E17: Teras Atiqah | F17: Yulia | G17: Vivi | H17: Pagi | I17: SMK Negeri 1 Ternate | J17: transportasi | L17: DANSAV MAKMUR | M17: LUNAS | P17: Pak Makmur
A18: 12 | B18: 46056 | C18: 444400 | D18: =C18 -> 444400 | E18: (Livin Mandiri) | F18: Yulia | G18: Vivi | H18: Siang | I18: Sofifi, Kantor DIKBUD | J18: BackDrop SMA N 5 Kota Ternate | K18: Kang Asep | L18: DANSAV UPY | M18: LUNAS
A19: 13 | B19: 46056 | C19: 103000 | D19: =C19 -> 103000 | E19: PLN(Livin Mandiri) | F19: Yulia | G19: Vivi | H19: Siang | I19: Sofifi, Kantor DIKBUD | J19: Pembelian TOKEN Lampu | K19: Pos 1 | L19: DANSAV UPY | M19: LUNAS
A20: 14 | B20: 46056 | C20: 103000 | D20: =C20 -> 103000 | E20: PLN(Livin Mandiri) | F20: Yulia | G20: Vivi | H20: Siang | I20: Sofifi, Kantor DIKBUD | J20: Pembelian TOKEN Lampu | K20: Pos 2 | L20: DANSAV UPY | M20: LUNAS
A21: 15 | B21: 46056 | C21: 900000 | D21: =C21 -> 900000 | E21: Pak Boby | F21: Yulia | G21: Vivi | H21: Pagi | I21: Sofifi, Kantor DIKBUD | J21: Jasa Kebersihan Pada Aula DIKBUD sofifi saat kegiatan pelantikan BMPS dan Serasehan Pendidikan periode 2026-2036 | K21: Pak Boby | L21: DANSAV UPY | M21: LUNAS
A22: 16 | D22: =C22 -> 0 | E22: Om ENgko | F22: Yulia | G22: Vivi | H22: Pagi | I22: Sofifi, Kantor DIKBUD | J22: Jasa Kebersihan Pada Aula DIKBUD sofifi saat kegiatan pelantikan BMPS dan Serasehan Pendidikan periode 2026-2036 | K22: Om ENgko | L22: DANSAV UPY | M22: LUNAS
A23: 17 | D23: =C23 -> 0 | E23: Yuli | F23: Yulia | G23: Vivi | H23: Pagi | I23: Sofifi, Kantor DIKBUD | J23: Jasa Kebersihan Pada Aula DIKBUD sofifi saat kegiatan pelantikan BMPS dan Serasehan Pendidikan periode 2026-2036 | K23: Yuli | L23: DANSAV UPY | M23: LUNAS
A24: 18 | D24: =C24 -> 0 | E24: Ona | F24: Yulia | G24: Vivi | H24: Pagi | I24: Sofifi, Kantor DIKBUD | J24: Jasa Kebersihan Pada Aula DIKBUD sofifi saat kegiatan pelantikan BMPS dan Serasehan Pendidikan periode 2026-2036 | K24: Ona | L24: DANSAV UPY | M24: LUNAS
A25: 19 | D25: =C25 -> 0 | E25: Kartini | F25: Yulia | G25: Vivi | H25: Pagi | I25: Sofifi, Kantor DIKBUD | J25: Jasa Kebersihan Pada Aula DIKBUD sofifi saat kegiatan pelantikan BMPS dan Serasehan Pendidikan periode 2026-2036 | K25: Kartini | L25: DANSAV UPY | M25: LUNAS
A26: 20 | D26: =C26 -> 0 | E26: Nurul | F26: Yulia | G26: Vivi | H26: Pagi | I26: Sofifi, Kantor DIKBUD | J26: Jasa Kebersihan Pada Aula DIKBUD sofifi saat kegiatan pelantikan BMPS dan Serasehan Pendidikan periode 2026-2036 | K26: Nurul | L26: DANSAV UPY | M26: LUNAS
A27: 21 | D27: =C27 -> 0 | E27: Pak Upy | F27: Yulia | G27: Vivi | H27: Pagi | I27: Sofifi, Kantor DIKBUD | J27: Jasa Kebersihan Pada Aula DIKBUD sofifi saat kegiatan pelantikan BMPS dan Serasehan Pendidikan periode 2026-2036 | K27: Pak Upy | L27: DANSAV UPY | M27: LUNAS
A28: 22 | D28: =C28 -> 0 | E28: Pak Sami | F28: Yulia | G28: Vivi | H28: Pagi | I28: Sofifi, Kantor DIKBUD | J28: Jasa Kebersihan Pada Aula DIKBUD sofifi saat kegiatan pelantikan BMPS dan Serasehan Pendidikan periode 2026-2036 | K28: Pak Sami | L28: DANSAV UPY | M28: LUNAS
A29: 23 | D29: =C29 -> 0 | E29: Adrian | F29: Yulia | G29: Vivi | H29: Pagi | I29: Sofifi, Kantor DIKBUD | J29: Jasa Kebersihan Pada Aula DIKBUD sofifi saat kegiatan pelantikan BMPS dan Serasehan Pendidikan periode 2026-2036 | K29: Adrian | L29: DANSAV UPY | M29: LUNAS
A30: 24 | B30: 46057 | C30: 6000000 | D30: =C30 -> 6000000 | E30: Teras Atiqah | F30: Yulia | G30: Vivi | H30: Pagi | I30: Sofifi, Kantor DIKBUD | J30: Mami RAPAT Kick Off Meeting | L30: DANSAV MAKMUR | M30: LUNAS | P30: Pak Makmur
A31: 25 | B31: 46057 | C31: 1200000 | D31: =C31 -> 1200000 | E31: Teluk Persia 2 | F31: Daffa | G31: Vivi | H31: Pagi | I31: Ternate, Pelabuhan SEMUT | J31: Kantor | L31: DANSAV MAKMUR | M31: LUNAS | P31: Pak Makmur
A32: 26 | B32: 46057 | C32: 1200000 | D32: =C32 -> 1200000 | E32: Teluk Persia 2 | F32: Daffa | G32: Vivi | H32: Sore | I32: Sofifi, Pelabuhan Spead Sofifi | J32: Balik | L32: DANSAV MAKMUR | M32: LUNAS | P32: Pak Makmur
A33: 27 | B33: 46057 | C33: 1000000 | D33: =C33 -> 1000000 | E33: Sekretaris KADIS | F33: Ayu | G33: Vivi | H33: Pagi | I33: Sofifi, Pelabuhan Spead Sofifi | J33: Makanan | L33: DANSAV MAKMUR | M33: LUNAS | P33: Pak Makmur
A34: 28 | B34: 46057 | C34: 1500000 | D34: =C34 -> 1500000 | E34: Ka vivi minta tf di rek BSI nya ka vivi | F34: Vivi | G34: Vivi | H34: Pagi | I34: Sofifi, Kantor DIKBUD | J34: - | L34: DANSAV UPY | M34: LUNAS
B35: 46057 | C35: 1000000 | D35: =C35 -> 1000000 | E35: KABID KEBUDAYAAN | F35: Vivi | G35: Vivi | H35: Pagi | I35: Sofifi, SPBU SOfifi | J35: Pembelian BBM KABID KEBUDAYAAN | L35: VIVI | M35: HUTANG
A36: 29 | C36: 1000000 | D36: =C36 -> 1000000 | E36: Ayu | F36: Yulia | G36: Vivi | H36: Pagi | I36: Sofifi, Kantor DIKBUD | J36: Makanan Kadis dan kue | L36: DANSAV MAKMUR | M36: LUNAS | P36: Pak Makmur
A37: 30 | B37: 46057 | C37: 6000000 | D37: 500000 | E37: Tribun Ternate | F37: Yulia | G37: Vivi | H37: Siang | I37: Sofifi, Kantor DIKBUD | J37: RAPAT Kick Off Meeting | L37: DANSAV MAKMUR | M37: LUNAS | P37: Pak Makmur
A38: 31 | D38: 500000 | E38: Warta Sofifi | F38: Yulia | G38: Vivi | H38: Siang | I38: Sofifi, Kantor DIKBUD | J38: RAPAT Kick Off Meeting | L38: DANSAV MAKMUR | M38: LUNAS | P38: Pak Makmur
A39: 32 | D39: 500000 | E39: Berita Baru com | F39: Yulia | G39: Vivi | H39: Siang | I39: Sofifi, Kantor DIKBUD | J39: RAPAT Kick Off Meeting | L39: DANSAV MAKMUR | M39: LUNAS | P39: Pak Makmur
A40: 33 | D40: 500000 | E40: RRI Ternate | F40: Yulia | G40: Vivi | H40: Siang | I40: Sofifi, Kantor DIKBUD | J40: RAPAT Kick Off Meeting | L40: DANSAV MAKMUR | M40: LUNAS | P40: Pak Makmur
A41: 34 | D41: 500000 | E41: Monitor Indonesia.com | F41: Yulia | G41: Vivi | H41: Siang | I41: Sofifi, Kantor DIKBUD | J41: RAPAT Kick Off Meeting | L41: DANSAV MAKMUR | M41: LUNAS | P41: Pak Makmur
A42: 35 | D42: 500000 | E42: Malut Post | F42: Yulia | G42: Vivi | H42: Siang | I42: Sofifi, Kantor DIKBUD | J42: RAPAT Kick Off Meeting | L42: DANSAV MAKMUR | M42: LUNAS | P42: Pak Makmur
...

Sheet Rincian_Saving_Feb
B1: SUMBER DANA : | C1: DANSAV MAKMUR | D1: <- PILIH DARI SINI | E1: Catatan : Data dalam tabel otomatis, jangan di rubah atau klik
A3: Hari, Tanggal | B3: Jumlah Nominal yang dikeluarkan | C3: Jumlah yang diterima | D3: Pihak Ke 3 | E3: Petugas Penerima | F3: Pejabat yang ditunjuk sbg Penerima | G3: Waktu Penyerahan | H3: Lokasi Penyerahan | I3: Tujuan/Keperluan
